<?xml version="1.0" encoding="utf-8"?>
<!-- This URDF was automatically created by SolidWorks to URDF Exporter! Originally created by Stephen Brawner (brawner@gmail.com) 
     Commit Version: 1.6.0-4-g7f85cfe  Build Version: 1.6.7995.38578
     For more information, please see http://wiki.ros.org/sw_urdf_exporter -->
<robot
  name="hopper_cmg_01">
  <link
    name="base_link">
    <inertial>
      <origin
        xyz="0.00205710480969474 0.000103468829143708 0.0218759927030672"
        rpy="0 0 0" />
      <mass
        value="4.33216790659109" />
      <inertia
        ixx="0.00379773001718443"
        ixy="-3.22398991976046E-06"
        ixz="5.54302878598966E-05"
        iyy="0.00606718252076055"
        iyz="8.35829380134359E-06"
        izz="0.00477430931356579" />
    </inertial>
    <visual>
      <origin
        xyz="0 0 0"
        rpy="0 0 0" />
      <geometry>
        <mesh
          filename="package://hopper_cmg_01/meshes/base_link.STL" />
      </geometry>
      <material
        name="">
        <color
          rgba="0.898039215686275 0.898039215686275 0.898039215686275 1" />
      </material>
    </visual>
    <collision>
      <origin
        xyz="0 0 0"
        rpy="0 0 0" />
      <geometry>
        <mesh
          filename="package://hopper_cmg_01/meshes/base_link.STL" />
      </geometry>
    </collision>
  </link>
  <link
    name="Link 0">
    <inertial>
      <origin
        xyz="0.0121851264299085 0.018088901394185 0.00112690392742548"
        rpy="0 0 0" />
      <mass
        value="0.256385566503952" />
      <inertia
        ixx="3.84650100874964E-05"
        ixy="1.5379784060096E-05"
        ixz="-8.48318798628566E-06"
        iyy="0.00017263374747093"
        iyz="1.08260201375488E-06"
        izz="0.000148822440720501" />
    </inertial>
    <visual>
      <origin
        xyz="0 0 0"
        rpy="0 0 0" />
      <geometry>
        <mesh
          filename="package://hopper_cmg_01/meshes/Link 0.STL" />
      </geometry>
      <material
        name="">
        <color
          rgba="0.898039215686275 0.898039215686275 0.898039215686275 1" />
      </material>
    </visual>
    <collision>
      <origin
        xyz="0 0 0"
        rpy="0 0 0" />
      <geometry>
        <mesh
          filename="package://hopper_cmg_01/meshes/Link 0.STL" />
      </geometry>
    </collision>
  </link>
  <joint
    name="Joint 0"
    type="revolute">
    <origin
      xyz="0 0 0"
      rpy="0 0.5235987755983 0" />
    <parent
      link="base_link" />
    <child
      link="Link 0" />
    <axis
      xyz="0 -1 0" />
    <limit
      lower="-3.14"
      upper="3.14"
      effort="0"
      velocity="0" />
  </joint>
  <link
    name="Link 1">
    <inertial>
      <origin
        xyz="0.133101645966311 0.00652998365272042 -1.77401565659707E-09"
        rpy="0 0 0" />
      <mass
        value="0.0631473819780702" />
      <inertia
        ixx="2.55548531328565E-06"
        ixy="6.97718053258012E-12"
        ixz="-1.43600151472767E-12"
        iyy="0.000104301911822778"
        iyz="7.22908067863827E-12"
        izz="0.000104301119173831" />
    </inertial>
    <visual>
      <origin
        xyz="0 0 0"
        rpy="0 0 0" />
      <geometry>
        <mesh
          filename="package://hopper_cmg_01/meshes/Link 1.STL" />
      </geometry>
      <material
        name="">
        <color
          rgba="0.776470588235294 0.756862745098039 0.737254901960784 1" />
      </material>
    </visual>
    <collision>
      <origin
        xyz="0 0 0"
        rpy="0 0 0" />
      <geometry>
        <mesh
          filename="package://hopper_cmg_01/meshes/Link 1.STL" />
      </geometry>
    </collision>
  </link>
  <joint
    name="Joint 1"
    type="revolute">
    <origin
      xyz="0.0999999999999999 0 0"
      rpy="-3.14159265358979 1.0768315178335 -3.14159265358979" />
    <parent
      link="Link 0" />
    <child
      link="Link 1" />
    <axis
      xyz="0 -1 0" />
    <limit
      lower="-0.7597"
      upper="1.8295"
      effort="0"
      velocity="0" />
  </joint>
  <link
    name="Link 2">
    <inertial>
      <origin
        xyz="0.0389032292366799 -0.0169313659858608 -0.000627148515342586"
        rpy="0 0 0" />
      <mass
        value="0.288845047026487" />
      <inertia
        ixx="3.46488303945479E-05"
        ixy="-3.25958703037608E-07"
        ixz="5.2492869432016E-06"
        iyy="0.000245584749831182"
        iyz="3.01080240182648E-08"
        izz="0.000226676365115679" />
    </inertial>
    <visual>
      <origin
        xyz="0 0 0"
        rpy="0 0 0" />
      <geometry>
        <mesh
          filename="package://hopper_cmg_01/meshes/Link 2.STL" />
      </geometry>
      <material
        name="">
        <color
          rgba="0.898039215686275 0.898039215686275 0.898039215686275 1" />
      </material>
    </visual>
    <collision>
      <origin
        xyz="0 0 0"
        rpy="0 0 0" />
      <geometry>
        <mesh
          filename="package://hopper_cmg_01/meshes/Link 2.STL" />
      </geometry>
    </collision>
  </link>
  <joint
    name="Joint 2"
    type="revolute">
    <origin
      xyz="0 0 0"
      rpy="3.14159265358979 0.553232742319403 -3.14159265358979" />
    <parent
      link="base_link" />
    <child
      link="Link 2" />
    <axis
      xyz="0 -1 0" />
    <limit
      lower="-3.14"
      upper="3.14"
      effort="0"
      velocity="0" />
  </joint>
  <link
    name="Link 3">
    <inertial>
      <origin
        xyz="0.101438166339763 -0.00251001126653755 -0.0148532865535596"
        rpy="0 0 0" />
      <mass
        value="0.124857598489408" />
      <inertia
        ixx="1.60742533765856E-05"
        ixy="-5.54606758491007E-07"
        ixz="1.00368165914556E-06"
        iyy="0.000116506433508525"
        iyz="1.07130613360585E-07"
        izz="0.000112946753522058" />
    </inertial>
    <visual>
      <origin
        xyz="0 0 0"
        rpy="0 0 0" />
      <geometry>
        <mesh
          filename="package://hopper_cmg_01/meshes/Link 3.STL" />
      </geometry>
      <material
        name="">
        <color
          rgba="1 1 1 1" />
      </material>
    </visual>
    <collision>
      <origin
        xyz="0 0 0"
        rpy="0 0 0" />
      <geometry>
        <mesh
          filename="package://hopper_cmg_01/meshes/Link 3.STL" />
      </geometry>
    </collision>
  </link>
  <joint
    name="Joint 3"
    type="revolute">
    <origin
      xyz="0.270000000042219 0 0"
      rpy="-3.14159265358979 -1.07683151743819 3.14159265358979" />
    <parent
      link="Link 2" />
    <child
      link="Link 3" />
    <axis
      xyz="0 -1 0" />
    <limit
      lower="-1.8295"
      upper="0.7597"
      effort="0"
      velocity="0" />
  </joint>
  <link
    name="gimbal0">
    <inertial>
      <origin
        xyz="-3.24494830612199E-05 -0.00476693855528867 -0.0330146895510202"
        rpy="0 0 0" />
      <mass
        value="0.145059238039555" />
      <inertia
        ixx="2.1627044716609E-05"
        ixy="-3.51182077407443E-08"
        ixz="-1.73128407882401E-09"
        iyy="2.68084681052019E-05"
        iyz="-1.59539178282102E-08"
        izz="1.56100643951685E-05" />
    </inertial>
    <visual>
      <origin
        xyz="0 0 0"
        rpy="0 0 0" />
      <geometry>
        <mesh
          filename="package://hopper_cmg_01/meshes/gimbal0.STL" />
      </geometry>
      <material
        name="">
        <color
          rgba="0.898039215686275 0.917647058823529 0.929411764705882 1" />
      </material>
    </visual>
    <collision>
      <origin
        xyz="0 0 0"
        rpy="0 0 0" />
      <geometry>
        <mesh
          filename="package://hopper_cmg_01/meshes/gimbal0.STL" />
      </geometry>
    </collision>
  </link>
  <joint
    name="joint_gimbal0"
    type="revolute">
    <origin
      xyz="0.027153 -0.15058 -0.018"
      rpy="-3.1416 0 0.7854" />
    <parent
      link="base_link" />
    <child
      link="gimbal0" />
    <axis
      xyz="0 0 1" />
    <limit
      lower="-1.57"
      upper="1.57"
      effort="0"
      velocity="0" />
  </joint>
  <link
    name="rw0">
    <inertial>
      <origin
        xyz="1.18130272369621E-07 -1.53730910321115E-07 -0.00582396682589451"
        rpy="0 0 0" />
      <mass
        value="0.10970736907618" />
      <inertia
        ixx="9.95338850353853E-05"
        ixy="8.58053417645318E-12"
        ixz="-7.74394638549476E-11"
        iyy="9.95339643952823E-05"
        iyz="8.9678247023017E-11"
        izz="0.000195642469806102" />
    </inertial>
    <visual>
      <origin
        xyz="0 0 0"
        rpy="0 0 0" />
      <geometry>
        <mesh
          filename="package://hopper_cmg_01/meshes/rw0.STL" />
      </geometry>
      <material
        name="">
        <color
          rgba="0.647058823529412 0.619607843137255 0.588235294117647 1" />
      </material>
    </visual>
    <collision>
      <origin
        xyz="0 0 0"
        rpy="0 0 0" />
      <geometry>
        <mesh
          filename="package://hopper_cmg_01/meshes/rw0.STL" />
      </geometry>
    </collision>
  </link>
  <joint
    name="joint_rw0"
    type="continuous">
    <origin
      xyz="0 0.0157238798738167 -0.0329999999999999"
      rpy="1.5707963267949 0.735922711393741 3.14159265358979" />
    <parent
      link="gimbal0" />
    <child
      link="rw0" />
    <axis
      xyz="0 0 -1" />
  </joint>
  <link
    name="gimbal1">
    <inertial>
      <origin
        xyz="-3.41102978538912E-05 -0.0047669338527654 -0.0329897477383744"
        rpy="0 0 0" />
      <mass
        value="0.145059130395345" />
      <inertia
        ixx="2.16762469579868E-05"
        ixy="-3.69526691947023E-08"
        ixz="5.81585232223255E-08"
        iyy="2.68084516491841E-05"
        iyz="1.10533926993815E-08"
        izz="1.55608357332489E-05" />
    </inertial>
    <visual>
      <origin
        xyz="0 0 0"
        rpy="0 0 0" />
      <geometry>
        <mesh
          filename="package://hopper_cmg_01/meshes/gimbal1.STL" />
      </geometry>
      <material
        name="">
        <color
          rgba="0.898039215686275 0.917647058823529 0.929411764705882 1" />
      </material>
    </visual>
    <collision>
      <origin
        xyz="0 0 0"
        rpy="0 0 0" />
      <geometry>
        <mesh
          filename="package://hopper_cmg_01/meshes/gimbal1.STL" />
      </geometry>
    </collision>
  </link>
  <joint
    name="joint_gimbal1"
    type="revolute">
    <origin
      xyz="0.11201 -0.065724 -0.018"
      rpy="-3.1416 0 0.7854" />
    <parent
      link="base_link" />
    <child
      link="gimbal1" />
    <axis
      xyz="0 0 1" />
    <limit
      lower="-1.57"
      upper="1.57"
      effort="0"
      velocity="0" />
  </joint>
  <link
    name="rw1">
    <inertial>
      <origin
        xyz="1.44339613242575E-07 1.11792372546604E-07 -0.00582396537224694"
        rpy="0 0 0" />
      <mass
        value="0.109707273892969" />
      <inertia
        ixx="9.95339577788371E-05"
        ixy="-5.43102249159089E-12"
        ixz="-8.62468737503092E-11"
        iyy="9.95338754847295E-05"
        iyz="-7.49619774721266E-11"
        izz="0.000195642459860242" />
    </inertial>
    <visual>
      <origin
        xyz="0 0 0"
        rpy="0 0 0" />
      <geometry>
        <mesh
          filename="package://hopper_cmg_01/meshes/rw1.STL" />
      </geometry>
      <material
        name="">
        <color
          rgba="0.647058823529412 0.619607843137255 0.588235294117647 1" />
      </material>
    </visual>
    <collision>
      <origin
        xyz="0 0 0"
        rpy="0 0 0" />
      <geometry>
        <mesh
          filename="package://hopper_cmg_01/meshes/rw1.STL" />
      </geometry>
    </collision>
  </link>
  <joint
    name="joint_rw1"
    type="continuous">
    <origin
      xyz="0 0.0157238798738165 -0.0329999999999999"
      rpy="-1.57079632679488 1.552198018793 0" />
    <parent
      link="gimbal1" />
    <child
      link="rw1" />
    <axis
      xyz="0 0 -1" />
  </joint>
  <link
    name="rwz">
    <inertial>
      <origin
        xyz="9.05342751461591E-09 -3.16385459497859E-10 -0.0146079871766002"
        rpy="0 0 0" />
      <mass
        value="0.377854494953543" />
      <inertia
        ixx="0.000300958121757204"
        ixy="-4.23471731313997E-12"
        ixz="-6.67153439547317E-12"
        iyy="0.000300957997312783"
        iyz="9.55842481655238E-14"
        izz="0.000578115934214616" />
    </inertial>
    <visual>
      <origin
        xyz="0 0 0"
        rpy="0 0 0" />
      <geometry>
        <mesh
          filename="package://hopper_cmg_01/meshes/rwz.STL" />
      </geometry>
      <material
        name="">
        <color
          rgba="0.647058823529412 0.619607843137255 0.588235294117647 1" />
      </material>
    </visual>
    <collision>
      <origin
        xyz="0 0 0"
        rpy="0 0 0" />
      <geometry>
        <mesh
          filename="package://hopper_cmg_01/meshes/rwz.STL" />
      </geometry>
    </collision>
  </link>
  <joint
    name="joint_rwz"
    type="continuous">
    <origin
      xyz="-0.076 0 0.0991000000000001"
      rpy="0 0 -2.35619449019233" />
    <parent
      link="base_link" />
    <child
      link="rwz" />
    <axis
      xyz="0 0 1" />
  </joint>
  <link
    name="gimbal2">
    <inertial>
      <origin
        xyz="-3.24494830613101E-05 -0.00476693855528879 -0.0330146895510203"
        rpy="0 0 0" />
      <mass
        value="0.145059238039555" />
      <inertia
        ixx="2.1627044716609E-05"
        ixy="-3.51182077407705E-08"
        ixz="-1.73128407883209E-09"
        iyy="2.6808468105202E-05"
        iyz="-1.59539178282325E-08"
        izz="1.56100643951684E-05" />
    </inertial>
    <visual>
      <origin
        xyz="0 0 0"
        rpy="0 0 0" />
      <geometry>
        <mesh
          filename="package://hopper_cmg_01/meshes/gimbal2.STL" />
      </geometry>
      <material
        name="">
        <color
          rgba="0.898039215686275 0.917647058823529 0.929411764705882 1" />
      </material>
    </visual>
    <collision>
      <origin
        xyz="0 0 0"
        rpy="0 0 0" />
      <geometry>
        <mesh
          filename="package://hopper_cmg_01/meshes/gimbal2.STL" />
      </geometry>
    </collision>
  </link>
  <joint
    name="joint_gimbal2"
    type="revolute">
    <origin
      xyz="0.11201 0.065724 -0.018"
      rpy="3.1416 0 2.3562" />
    <parent
      link="base_link" />
    <child
      link="gimbal2" />
    <axis
      xyz="0 0 1" />
    <limit
      lower="-1.57"
      upper="1.57"
      effort="0"
      velocity="0" />
  </joint>
  <link
    name="rw2">
    <inertial>
      <origin
        xyz="1.18130272369621E-07 -1.53730910432137E-07 -0.00582396682589442"
        rpy="0 0 0" />
      <mass
        value="0.10970736907618" />
      <inertia
        ixx="9.95338850353859E-05"
        ixy="8.58053420186417E-12"
        ixz="-7.74394639023815E-11"
        iyy="9.95339643952829E-05"
        iyz="8.9678247023017E-11"
        izz="0.000195642469806104" />
    </inertial>
    <visual>
      <origin
        xyz="0 0 0"
        rpy="0 0 0" />
      <geometry>
        <mesh
          filename="package://hopper_cmg_01/meshes/rw2.STL" />
      </geometry>
      <material
        name="">
        <color
          rgba="0.647058823529412 0.619607843137255 0.588235294117647 1" />
      </material>
    </visual>
    <collision>
      <origin
        xyz="0 0 0"
        rpy="0 0 0" />
      <geometry>
        <mesh
          filename="package://hopper_cmg_01/meshes/rw2.STL" />
      </geometry>
    </collision>
  </link>
  <joint
    name="joint_rw2"
    type="continuous">
    <origin
      xyz="0 0.0157238798738165 -0.033"
      rpy="1.5707963267949 0.73592271139374 -3.14159265358979" />
    <parent
      link="gimbal2" />
    <child
      link="rw2" />
    <axis
      xyz="0 0 -1" />
  </joint>
  <link
    name="gimbal3">
    <inertial>
      <origin
        xyz="-3.41103479271632E-05 -0.00476693386081009 -0.0329897477404721"
        rpy="0 0 0" />
      <mass
        value="0.145059131410169" />
      <inertia
        ixx="2.16762469514495E-05"
        ixy="-3.69526817014293E-08"
        ixz="5.81585215101624E-08"
        iyy="2.68084517015779E-05"
        iyz="1.10533963414748E-08"
        izz="1.55608357842301E-05" />
    </inertial>
    <visual>
      <origin
        xyz="0 0 0"
        rpy="0 0 0" />
      <geometry>
        <mesh
          filename="package://hopper_cmg_01/meshes/gimbal3.STL" />
      </geometry>
      <material
        name="">
        <color
          rgba="0.898039215686275 0.917647058823529 0.929411764705882 1" />
      </material>
    </visual>
    <collision>
      <origin
        xyz="0 0 0"
        rpy="0 0 0" />
      <geometry>
        <mesh
          filename="package://hopper_cmg_01/meshes/gimbal3.STL" />
      </geometry>
    </collision>
  </link>
  <joint
    name="joint_gimbal3"
    type="revolute">
    <origin
      xyz="0.027153 0.15058 -0.018"
      rpy="3.1416 0 2.3562" />
    <parent
      link="base_link" />
    <child
      link="gimbal3" />
    <axis
      xyz="0 0 1" />
    <limit
      lower="-1.57"
      upper="1.57"
      effort="0"
      velocity="0" />
  </joint>
  <link
    name="rw3">
    <inertial>
      <origin
        xyz="1.44339613383088E-07 1.11792372622932E-07 -0.00582396537224694"
        rpy="0 0 0" />
      <mass
        value="0.109707273892969" />
      <inertia
        ixx="9.95339577788376E-05"
        ixy="-5.43102247973243E-12"
        ixz="-8.6246873737392E-11"
        iyy="9.95338754847298E-05"
        iyz="-7.49619774958435E-11"
        izz="0.000195642459860243" />
    </inertial>
    <visual>
      <origin
        xyz="0 0 0"
        rpy="0 0 0" />
      <geometry>
        <mesh
          filename="package://hopper_cmg_01/meshes/rw3.STL" />
      </geometry>
      <material
        name="">
        <color
          rgba="0.898039215686275 0.898039215686275 0.898039215686275 1" />
      </material>
    </visual>
    <collision>
      <origin
        xyz="0 0 0"
        rpy="0 0 0" />
      <geometry>
        <mesh
          filename="package://hopper_cmg_01/meshes/rw3.STL" />
      </geometry>
    </collision>
  </link>
  <joint
    name="joint_rw3"
    type="continuous">
    <origin
      xyz="0 0.0157238798738165 -0.033"
      rpy="-1.57079632679489 1.552198018793 0" />
    <parent
      link="gimbal3" />
    <child
      link="rw3" />
    <axis
      xyz="0 0 -1" />
  </joint>
</robot>