<?xml version="1.0" encoding="utf-8"?>
<!-- This URDF was automatically created by SolidWorks to URDF Exporter! Originally created by Stephen Brawner (brawner@gmail.com) 
     Commit Version: 1.6.0-1-g15f4949  Build Version: 1.6.7594.29634
     For more information, please see http://wiki.ros.org/sw_urdf_exporter -->
<robot
  name="cmg_mockup">
  <link
    name="base_link">
    <inertial>
      <origin
        xyz="2.04621790177729E-19 8.32716201197779E-21 -0.00453036363805971"
        rpy="0 0 0" />
      <mass
        value="0.0179726942298267" />
      <inertia
        ixx="1.65261736708293E-06"
        ixy="-5.05624879079861E-23"
        ixz="-1.1130256547726E-22"
        iyy="1.48252036342011E-06"
        iyz="-1.07343474858583E-22"
        izz="1.3425053205757E-06" />
    </inertial>
    <visual>
      <origin
        xyz="0 0 0"
        rpy="0 0 0" />
      <geometry>
        <mesh
          filename="package://cmg_mockup/meshes/base_link.STL" />
      </geometry>
      <material
        name="">
        <color
          rgba="0.898039215686275 0.917647058823529 0.929411764705882 1" />
      </material>
    </visual>
    <collision>
      <origin
        xyz="0 0 0"
        rpy="0 0 0" />
      <geometry>
        <mesh
          filename="package://cmg_mockup/meshes/base_link.STL" />
      </geometry>
    </collision>
  </link>
  <link
    name="frame">
    <inertial>
      <origin
        xyz="1.11958587767099E-17 8.61613300303699E-10 0.183985949426508"
        rpy="0 0 0" />
      <mass
        value="0.135843181460511" />
      <inertia
        ixx="0.00135654985342586"
        ixy="6.75768354822669E-11"
        ixz="7.31996954916908E-20"
        iyy="0.00132064999849433"
        iyz="-8.03639604769252E-12"
        izz="7.25202012105515E-05" />
    </inertial>
    <visual>
      <origin
        xyz="0 0 0"
        rpy="0 0 0" />
      <geometry>
        <mesh
          filename="package://cmg_mockup/meshes/frame.STL" />
      </geometry>
      <material
        name="">
        <color
          rgba="0.898039215686275 0.917647058823529 0.929411764705882 1" />
      </material>
    </visual>
    <collision>
      <origin
        xyz="0 0 0"
        rpy="0 0 0" />
      <geometry>
        <mesh
          filename="package://cmg_mockup/meshes/frame.STL" />
      </geometry>
    </collision>
  </link>
  <joint
    name="joint0"
    type="revolute">
    <origin
      xyz="0 0 0"
      rpy="0 0 0" />
    <parent
      link="base_link" />
    <child
      link="frame" />
    <axis
      xyz="0 1 0" />
    <limit
      lower="0"
      upper="0"
      effort="0"
      velocity="0" />
  </joint>
  <link
    name="gimbal1">
    <inertial>
      <origin
        xyz="-6.15027795000011E-18 0 5.55111512312578E-17"
        rpy="0 0 0" />
      <mass
        value="0.00730600065730224" />
      <inertia
        ixx="5.14476869835539E-07"
        ixy="5.72219288718141E-22"
        ixz="1.31049057483626E-22"
        iyy="2.49838326078774E-06"
        iyz="2.30858111807237E-23"
        izz="2.44215073098293E-06" />
    </inertial>
    <visual>
      <origin
        xyz="0 0 0"
        rpy="0 0 0" />
      <geometry>
        <mesh
          filename="package://cmg_mockup/meshes/gimbal1.STL" />
      </geometry>
      <material
        name="">
        <color
          rgba="0.792156862745098 0.819607843137255 0.933333333333333 1" />
      </material>
    </visual>
    <collision>
      <origin
        xyz="0 0 0"
        rpy="0 0 0" />
      <geometry>
        <mesh
          filename="package://cmg_mockup/meshes/gimbal1.STL" />
      </geometry>
    </collision>
  </link>
  <joint
    name="joint1"
    type="revolute">
    <origin
      xyz="0 -0.022 0.3"
      rpy="0 0 0" />
    <parent
      link="frame" />
    <child
      link="gimbal1" />
    <axis
      xyz="-1 0 0" />
    <limit
      lower="0"
      upper="0"
      effort="0"
      velocity="0" />
  </joint>
  <link
    name="flywheel1">
    <inertial>
      <origin
        xyz="-5.50575632364296E-18 -3.46944695195361E-18 -0.000257572459907096"
        rpy="0 0 0" />
      <mass
        value="0.0115837700311142" />
      <inertia
        ixx="1.69787427560436E-06"
        ixy="5.71998624754687E-22"
        ixz="-1.21376645313962E-23"
        iyy="1.69787427560436E-06"
        iyz="1.69168888618569E-23"
        izz="3.36639551515697E-06" />
    </inertial>
    <visual>
      <origin
        xyz="0 0 0"
        rpy="0 0 0" />
      <geometry>
        <mesh
          filename="package://cmg_mockup/meshes/flywheel1.STL" />
      </geometry>
      <material
        name="">
        <color
          rgba="0.647058823529412 0.619607843137255 0.588235294117647 1" />
      </material>
    </visual>
    <collision>
      <origin
        xyz="0 0 0"
        rpy="0 0 0" />
      <geometry>
        <mesh
          filename="package://cmg_mockup/meshes/flywheel1.STL" />
      </geometry>
    </collision>
  </link>
  <joint
    name="joint2"
    type="continuous">
    <origin
      xyz="0 0 0"
      rpy="0 0 0" />
    <parent
      link="gimbal1" />
    <child
      link="flywheel1" />
    <axis
      xyz="0 0 -1" />
  </joint>
  <link
    name="gimbal2">
    <inertial>
      <origin
        xyz="1.66565579259142E-18 0 -5.55111512312578E-17"
        rpy="0 0 0" />
      <mass
        value="0.00730600065730224" />
      <inertia
        ixx="5.14476869835539E-07"
        ixy="-5.72539034555591E-23"
        ixz="1.34393827721763E-22"
        iyy="2.49838326078774E-06"
        iyz="8.26100188657236E-24"
        izz="2.44215073098293E-06" />
    </inertial>
    <visual>
      <origin
        xyz="0 0 0"
        rpy="0 0 0" />
      <geometry>
        <mesh
          filename="package://cmg_mockup/meshes/gimbal2.STL" />
      </geometry>
      <material
        name="">
        <color
          rgba="0.792156862745098 0.819607843137255 0.933333333333333 1" />
      </material>
    </visual>
    <collision>
      <origin
        xyz="0 0 0"
        rpy="0 0 0" />
      <geometry>
        <mesh
          filename="package://cmg_mockup/meshes/gimbal2.STL" />
      </geometry>
    </collision>
  </link>
  <joint
    name="joint3"
    type="revolute">
    <origin
      xyz="0 0.022 0.3"
      rpy="0 0 0" />
    <parent
      link="frame" />
    <child
      link="gimbal2" />
    <axis
      xyz="-1 0 0" />
    <limit
      lower="0"
      upper="0"
      effort="0"
      velocity="0" />
  </joint>
  <link
    name="flywheel2">
    <inertial>
      <origin
        xyz="-8.42997684618261E-18 6.93889390390723E-18 -0.000257572459907152"
        rpy="0 0 0" />
      <mass
        value="0.0115837700311142" />
      <inertia
        ixx="1.69787427560436E-06"
        ixy="8.37358811496551E-22"
        ixz="-3.18292437291809E-22"
        iyy="1.69787427560436E-06"
        iyz="1.34525792568568E-23"
        izz="3.36639551515697E-06" />
    </inertial>
    <visual>
      <origin
        xyz="0 0 0"
        rpy="0 0 0" />
      <geometry>
        <mesh
          filename="package://cmg_mockup/meshes/flywheel2.STL" />
      </geometry>
      <material
        name="">
        <color
          rgba="0.647058823529412 0.619607843137255 0.588235294117647 1" />
      </material>
    </visual>
    <collision>
      <origin
        xyz="0 0 0"
        rpy="0 0 0" />
      <geometry>
        <mesh
          filename="package://cmg_mockup/meshes/flywheel2.STL" />
      </geometry>
    </collision>
  </link>
  <joint
    name="joint4"
    type="continuous">
    <origin
      xyz="0 0 0"
      rpy="0 0 0" />
    <parent
      link="gimbal2" />
    <child
      link="flywheel2" />
    <axis
      xyz="0 0 -1" />
  </joint>
</robot>