<?xml version="1.0" encoding="utf-8"?>
<!-- This URDF was automatically created by SolidWorks to URDF Exporter! Originally created by Stephen Brawner (brawner@gmail.com) 
     Commit Version: 1.5.1-0-g916b5db  Build Version: 1.5.7152.31018
     For more information, please see http://wiki.ros.org/sw_urdf_exporter -->
<robot
  name="hopper_rev08">
  <link
    name="base_link">
    <inertial>
      <origin
        xyz="-0.00175503010472917 0.000152527313137044 0.0164393216803801"
        rpy="0 0 0" />
      <mass
        value="4.51400070312395" />
      <inertia
        ixx="0.00367840947099141"
        ixy="-3.23576007169648E-06"
        ixz="0.000274535262368248"
        iyy="0.00493046649237446"
        iyz="1.22323181861546E-05"
        izz="0.00365832998427976" />
    </inertial>
    <visual>
      <origin
        xyz="0 0 0"
        rpy="0 0 0" />
      <geometry>
        <mesh
          filename="package://hopper_rev08/meshes/base_link.STL" />
      </geometry>
      <material
        name="">
        <color
          rgba="0.898039215686275 0.917647058823529 0.929411764705882 1" />
      </material>
    </visual>
    <collision>
      <origin
        xyz="0 0 0"
        rpy="0 0 0" />
      <geometry>
        <mesh
          filename="package://hopper_rev08/meshes/base_link.STL" />
      </geometry>
    </collision>
  </link>
  <link
    name="Link 0">
    <inertial>
      <origin
        xyz="0.00532254723786838 0.0312919322159349 0.000492240042371901"
        rpy="0 0 0" />
      <mass
        value="0.586954605797748" />
      <inertia
        ixx="0.000227426543743824"
        ixy="1.53798003742491E-05"
        ixz="-8.48629875488119E-06"
        iyy="0.000542296778294892"
        iyz="1.08258982588965E-06"
        izz="0.000337787614156298" />
    </inertial>
    <visual>
      <origin
        xyz="0 0 0"
        rpy="0 0 0" />
      <geometry>
        <mesh
          filename="package://hopper_rev08/meshes/Link 0.STL" />
      </geometry>
      <material
        name="">
        <color
          rgba="0.898039215686275 0.917647058823529 0.929411764705882 1" />
      </material>
    </visual>
    <collision>
      <origin
        xyz="0 0 0"
        rpy="0 0 0" />
      <geometry>
        <mesh
          filename="package://hopper_rev08/meshes/Link 0.STL" />
      </geometry>
    </collision>
  </link>
  <joint
    name="Joint 0"
    type="revolute">
    <origin
      xyz="0 0 0"
      rpy="0 0.5236 0" />
    <parent
      link="base_link" />
    <child
      link="Link 0" />
    <axis
      xyz="0 -1 0" />
    <limit
      lower="-3.14"
      upper="3.14"
      effort="0"
      velocity="0" />
  </joint>
  <link
    name="Link 1">
    <inertial>
      <origin
        xyz="0.13310164596639 0.00662597443711811 -1.77401791867648E-09"
        rpy="0 0 0" />
      <mass
        value="0.0631473819780334" />
      <inertia
        ixx="2.55548531328052E-06"
        ixy="6.97717874493083E-12"
        ixz="-1.43600066854176E-12"
        iyy="0.000104301911822778"
        iyz="7.22908180570549E-12"
        izz="0.000104301119173826" />
    </inertial>
    <visual>
      <origin
        xyz="0 0 0"
        rpy="0 0 0" />
      <geometry>
        <mesh
          filename="package://hopper_rev08/meshes/Link 1.STL" />
      </geometry>
      <material
        name="">
        <color
          rgba="0.776470588235294 0.756862745098039 0.737254901960784 1" />
      </material>
    </visual>
    <collision>
      <origin
        xyz="0 0 0"
        rpy="0 0 0" />
      <geometry>
        <mesh
          filename="package://hopper_rev08/meshes/Link 1.STL" />
      </geometry>
    </collision>
  </link>
  <joint
    name="Joint 1"
    type="revolute">
    <origin
      xyz="0.1 0 0"
      rpy="3.1416 1.0768 3.1416" />
    <parent
      link="Link 0" />
    <child
      link="Link 1" />
    <axis
      xyz="0 -1 0" />
    <limit
      lower="-0.7597"
      upper="1.8295"
      effort="0"
      velocity="0" />
  </joint>
  <link
    name="Link 2">
    <inertial>
      <origin
        xyz="0.0181413414326611 -0.0300644982462197 -0.000292456416569055"
        rpy="0 0 0" />
      <mass
        value="0.619414111352979" />
      <inertia
        ixx="0.000223610216059139"
        ixy="-3.25959928890848E-07"
        ixz="5.24627039602807E-06"
        iyy="0.000615247781706059"
        iyz="3.01269748941687E-08"
        izz="0.000415641686191928" />
    </inertial>
    <visual>
      <origin
        xyz="0 0 0"
        rpy="0 0 0" />
      <geometry>
        <mesh
          filename="package://hopper_rev08/meshes/Link 2.STL" />
      </geometry>
      <material
        name="">
        <color
          rgba="0.898039215686275 0.917647058823529 0.929411764705882 1" />
      </material>
    </visual>
    <collision>
      <origin
        xyz="0 0 0"
        rpy="0 0 0" />
      <geometry>
        <mesh
          filename="package://hopper_rev08/meshes/Link 2.STL" />
      </geometry>
    </collision>
  </link>
  <joint
    name="Joint 2"
    type="revolute">
    <origin
      xyz="0 0 0"
      rpy="3.1416 0.55323 3.1416" />
    <parent
      link="base_link" />
    <child
      link="Link 2" />
    <axis
      xyz="0 -1 0" />
    <limit
      lower="-3.14"
      upper="3.14"
      effort="0"
      velocity="0" />
  </joint>
  <link
    name="Link 3">
    <inertial>
      <origin
        xyz="0.101438168534655 -0.00250998138733511 -0.0148532860240944"
        rpy="0 0 0" />
      <mass
        value="0.124857600438339" />
      <inertia
        ixx="1.60742533918104E-05"
        ixy="-5.54606498912151E-07"
        ixz="1.00368232128696E-06"
        iyy="0.000116506434452896"
        iyz="1.07130350261427E-07"
        izz="0.000112946753727812" />
    </inertial>
    <visual>
      <origin
        xyz="0 0 0"
        rpy="0 0 0" />
      <geometry>
        <mesh
          filename="package://hopper_rev08/meshes/Link 3.STL" />
      </geometry>
      <material
        name="">
        <color
          rgba="1 1 1 1" />
      </material>
    </visual>
    <collision>
      <origin
        xyz="0 0 0"
        rpy="0 0 0" />
      <geometry>
        <mesh
          filename="package://hopper_rev08/meshes/Link 3.STL" />
      </geometry>
    </collision>
  </link>
  <joint
    name="Joint 3"
    type="revolute">
    <origin
      xyz="0.27 0 0"
      rpy="-3.1416 -1.0768 3.1416" />
    <parent
      link="Link 2" />
    <child
      link="Link 3" />
    <axis
      xyz="0 -1 0" />
    <limit
      lower="-1.8295"
      upper="0.7597"
      effort="0"
      velocity="0" />
  </joint>
  <link
    name="rw0">
    <inertial>
      <origin
        xyz="-0.0115567063467111 -9.87030621124596E-09 -5.44727483397052E-10"
        rpy="0 0 0" />
      <mass
        value="0.711638774644899" />
      <inertia
        ixx="0.00353741807101941"
        ixy="-2.02247671192944E-11"
        ixz="-2.13661861867115E-11"
        iyy="0.00179202767102953"
        iyz="1.17051665560957E-11"
        izz="0.00179202753958039" />
    </inertial>
    <visual>
      <origin
        xyz="0 0 0"
        rpy="0 0 0" />
      <geometry>
        <mesh
          filename="package://hopper_rev08/meshes/rw0.STL" />
      </geometry>
      <material
        name="">
        <color
          rgba="0.647058823529412 0.619607843137255 0.588235294117647 1" />
      </material>
    </visual>
    <collision>
      <origin
        xyz="0 0 0"
        rpy="0 0 0" />
      <geometry>
        <mesh
          filename="package://hopper_rev08/meshes/rw0.STL" />
      </geometry>
    </collision>
  </link>
  <joint
    name="joint_rw0"
    type="continuous">
    <origin
      xyz="0.056569 -0.1372 0"
      rpy="3.1416 0 -0.7854" />
    <parent
      link="base_link" />
    <child
      link="rw0" />
    <axis
      xyz="-1 0 0" />
  </joint>
  <link
    name="rw1">
    <inertial>
      <origin
        xyz="-0.0115568758230247 9.87647955086324E-09 5.55701687190008E-10"
        rpy="0 0 0" />
      <mass
        value="0.711638774351903" />
      <inertia
        ixx="0.00353741806943413"
        ixy="2.02143131335271E-11"
        ixz="2.13499682946752E-11"
        iyy="0.00179202767033281"
        iyz="1.15301454856464E-11"
        izz="0.00179202753869205" />
    </inertial>
    <visual>
      <origin
        xyz="0 0 0"
        rpy="0 0 0" />
      <geometry>
        <mesh
          filename="package://hopper_rev08/meshes/rw1.STL" />
      </geometry>
      <material
        name="">
        <color
          rgba="0.647058823529412 0.619607843137255 0.588235294117647 1" />
      </material>
    </visual>
    <collision>
      <origin
        xyz="0 0 0"
        rpy="0 0 0" />
      <geometry>
        <mesh
          filename="package://hopper_rev08/meshes/rw1.STL" />
      </geometry>
    </collision>
  </link>
  <joint
    name="joint_rw1"
    type="continuous">
    <origin
      xyz="0.056569 0.1372 0"
      rpy="0 0 0.7854" />
    <parent
      link="base_link" />
    <child
      link="rw1" />
    <axis
      xyz="-1 0 0" />
  </joint>
  <link
    name="rwz">
    <inertial>
      <origin
        xyz="1.51930469594053E-09 -2.24012364567906E-09 -0.0088575158066873"
        rpy="0 0 0" />
      <mass
        value="0.356354012275079" />
      <inertia
        ixx="0.000387758083080237"
        ixy="-1.70707272380331E-09"
        ixz="7.35539719441431E-12"
        iyy="0.000387758098776146"
        iyz="-1.15377941738063E-11"
        izz="0.000767191620605786" />
    </inertial>
    <visual>
      <origin
        xyz="0 0 0"
        rpy="0 0 0" />
      <geometry>
        <mesh
          filename="package://hopper_rev08/meshes/rwz.STL" />
      </geometry>
      <material
        name="">
        <color
          rgba="0.647058823529412 0.619607843137255 0.588235294117647 1" />
      </material>
    </visual>
    <collision>
      <origin
        xyz="0 0 0"
        rpy="0 0 0" />
      <geometry>
        <mesh
          filename="package://hopper_rev08/meshes/rwz.STL" />
      </geometry>
    </collision>
  </link>
  <joint
    name="joint_rwz"
    type="continuous">
    <origin
      xyz="-0.076 0 0.0834999999999998"
      rpy="0 0 -3.14159265358978" />
    <parent
      link="base_link" />
    <child
      link="rwz" />
    <axis
      xyz="0 0 -1" />
  </joint>
</robot>