<?xml version="1.0" encoding="utf-8"?>
<!-- This URDF was automatically created by SolidWorks to URDF Exporter! Originally created by Stephen Brawner (brawner@gmail.com) 
     Commit Version: 1.5.1-0-g916b5db  Build Version: 1.5.7152.31018
     For more information, please see http://wiki.ros.org/sw_urdf_exporter -->
<robot
  name="flyhopper_mockup">
  <link
    name="base_link">
    <inertial>
      <origin
        xyz="2.95315815186336E-21 -5.28321611633813E-18 -6.04703832882441E-34"
        rpy="0 0 0" />
      <mass
        value="4.12611894583318" />
      <inertia
        ixx="0.016545729792484"
        ixy="8.31981182398873E-20"
        ixz="-1.26926390026546E-24"
        iyy="0.0167520362912236"
        iyz="-2.85176098350281E-21"
        izz="0.0165457505218212" />
    </inertial>
    <visual>
      <origin
        xyz="0 0 0"
        rpy="0 0 0" />
      <geometry>
        <mesh
          filename="package://flyhopper_mockup/meshes/base_link.STL" />
      </geometry>
      <material
        name="">
        <color
          rgba="0.792156862745098 0.819607843137255 0.933333333333333 1" />
      </material>
    </visual>
    <collision>
      <origin
        xyz="0 0 0"
        rpy="0 0 0" />
      <geometry>
        <mesh
          filename="package://flyhopper_mockup/meshes/base_link.STL" />
      </geometry>
    </collision>
  </link>
  <link
    name="Link 1">
    <inertial>
      <origin
        xyz="-0.15 -1.76689249496647E-17 2.77555756156289E-17"
        rpy="0 0 0" />
      <mass
        value="0.624823001646925" />
      <inertia
        ixx="0.000227946900494079"
        ixy="7.57340254057453E-20"
        ixz="5.0821976835258E-19"
        iyy="0.00648268788779692"
        iyz="-2.42553659567009E-20"
        izz="0.00634846443754988" />
    </inertial>
    <visual>
      <origin
        xyz="0 0 0"
        rpy="0 0 0" />
      <geometry>
        <mesh
          filename="package://flyhopper_mockup/meshes/Link 1.STL" />
      </geometry>
      <material
        name="">
        <color
          rgba="0.792156862745098 0.819607843137255 0.933333333333333 1" />
      </material>
    </visual>
    <collision>
      <origin
        xyz="0 0 0"
        rpy="0 0 0" />
      <geometry>
        <mesh
          filename="package://flyhopper_mockup/meshes/Link 1.STL" />
      </geometry>
    </collision>
  </link>
  <joint
    name="Joint 1"
    type="revolute">
    <origin
      xyz="-0.25981 0 -0.15"
      rpy="3.1416 0.5236 3.1416" />
    <parent
      link="base_link" />
    <child
      link="Link 1" />
    <axis
      xyz="0 -1 0" />
    <limit
      lower="-3.14"
      upper="3.14"
      effort="0"
      velocity="0" />
  </joint>
  <link
    name="Link 2">
    <inertial>
      <origin
        xyz="-0.15 -1.94036484256415E-17 0"
        rpy="0 0 0" />
      <mass
        value="0.624823001646924" />
      <inertia
        ixx="0.000227946900494075"
        ixy="-1.3267640809063E-20"
        ixz="1.23327997120226E-18"
        iyy="0.0064826878877969"
        iyz="4.94500075795682E-20"
        izz="0.00634846443754987" />
    </inertial>
    <visual>
      <origin
        xyz="0 0 0"
        rpy="0 0 0" />
      <geometry>
        <mesh
          filename="package://flyhopper_mockup/meshes/Link 2.STL" />
      </geometry>
      <material
        name="">
        <color
          rgba="0.792156862745098 0.819607843137255 0.933333333333333 1" />
      </material>
    </visual>
    <collision>
      <origin
        xyz="0 0 0"
        rpy="0 0 0" />
      <geometry>
        <mesh
          filename="package://flyhopper_mockup/meshes/Link 2.STL" />
      </geometry>
    </collision>
  </link>
  <joint
    name="Joint 2"
    type="revolute">
    <origin
      xyz="-0.15 0 0.25981"
      rpy="3.1416 -1.0472 3.1416" />
    <parent
      link="Link 1" />
    <child
      link="Link 2" />
    <axis
      xyz="0 -1 0" />
    <limit
      lower="-3.14"
      upper="3.14"
      effort="0"
      velocity="0" />
  </joint>
</robot>