<?xml version="1.0" encoding="utf-8"?>
<!-- This URDF was automatically created by SolidWorks to URDF Exporter! Originally created by Stephen Brawner (brawner@gmail.com) 
     Commit Version: 1.6.0-4-g7f85cfe  Build Version: 1.6.7995.38578
     For more information, please see http://wiki.ros.org/sw_urdf_exporter -->
<robot
  name="hopper_cmg">
  <link
    name="base_link">
    <inertial>
      <origin
        xyz="0.00261236312196263 0.000103468861747552 0.022500687974853"
        rpy="0 0 0" />
      <mass
        value="4.33217212032757" />
      <inertia
        ixx="0.00375815397665076"
        ixy="-3.2239869384024E-06"
        ixz="5.54302905240728E-05"
        iyy="0.00602760648024803"
        iyz="8.35763269355205E-06"
        izz="0.00485347607828087" />
    </inertial>
    <visual>
      <origin
        xyz="0 0 0"
        rpy="0 0 0" />
      <geometry>
        <mesh
          filename="package://hopper_cmg/meshes/base_link.STL" />
      </geometry>
      <material
        name="">
        <color
          rgba="0.898039215686275 0.898039215686275 0.898039215686275 1" />
      </material>
    </visual>
    <collision>
      <origin
        xyz="0 0 0"
        rpy="0 0 0" />
      <geometry>
        <mesh
          filename="package://hopper_cmg/meshes/base_link.STL" />
      </geometry>
    </collision>
  </link>
  <link
    name="Link 0">
    <inertial>
      <origin
        xyz="0.0121851264299085 0.018088901394185 0.00112690392742548"
        rpy="0 0 0" />
      <mass
        value="0.256385566503952" />
      <inertia
        ixx="3.84650100874964E-05"
        ixy="1.5379784060096E-05"
        ixz="-8.48318798628566E-06"
        iyy="0.00017263374747093"
        iyz="1.08260201375488E-06"
        izz="0.000148822440720501" />
    </inertial>
    <visual>
      <origin
        xyz="0 0 0"
        rpy="0 0 0" />
      <geometry>
        <mesh
          filename="package://hopper_cmg/meshes/Link 0.STL" />
      </geometry>
      <material
        name="">
        <color
          rgba="0.898039215686275 0.898039215686275 0.898039215686275 1" />
      </material>
    </visual>
    <collision>
      <origin
        xyz="0 0 0"
        rpy="0 0 0" />
      <geometry>
        <mesh
          filename="package://hopper_cmg/meshes/Link 0.STL" />
      </geometry>
    </collision>
  </link>
  <joint
    name="Joint 0"
    type="revolute">
    <origin
      xyz="0 0 0"
      rpy="0 0.5235987755983 0" />
    <parent
      link="base_link" />
    <child
      link="Link 0" />
    <axis
      xyz="0 -1 0" />
    <limit
      lower="-3.14"
      upper="3.14"
      effort="0"
      velocity="0" />
  </joint>
  <link
    name="Link 1">
    <inertial>
      <origin
        xyz="0.133101645966311 0.00652998365272101 -1.77401554557477E-09"
        rpy="0 0 0" />
      <mass
        value="0.0631473819780702" />
      <inertia
        ixx="2.55548531328565E-06"
        ixy="6.97718053252048E-12"
        ixz="-1.4360015252097E-12"
        iyy="0.000104301911822778"
        iyz="7.2290806785121E-12"
        izz="0.000104301119173831" />
    </inertial>
    <visual>
      <origin
        xyz="0 0 0"
        rpy="0 0 0" />
      <geometry>
        <mesh
          filename="package://hopper_cmg/meshes/Link 1.STL" />
      </geometry>
      <material
        name="">
        <color
          rgba="0.776470588235294 0.756862745098039 0.737254901960784 1" />
      </material>
    </visual>
    <collision>
      <origin
        xyz="0 0 0"
        rpy="0 0 0" />
      <geometry>
        <mesh
          filename="package://hopper_cmg/meshes/Link 1.STL" />
      </geometry>
    </collision>
  </link>
  <joint
    name="Joint 1"
    type="revolute">
    <origin
      xyz="0.0999999999999999 0 0"
      rpy="-3.14159265358979 1.0768315178335 -3.14159265358979" />
    <parent
      link="Link 0" />
    <child
      link="Link 1" />
    <axis
      xyz="0 -1 0" />
    <limit
      lower="-0.7597"
      upper="1.8295"
      effort="0"
      velocity="0" />
  </joint>
  <link
    name="Link 2">
    <inertial>
      <origin
        xyz="0.0389032292366799 -0.0169313659858608 -0.000627148515342589"
        rpy="0 0 0" />
      <mass
        value="0.288845047026487" />
      <inertia
        ixx="3.46488303945479E-05"
        ixy="-3.25958703037608E-07"
        ixz="5.24928694320162E-06"
        iyy="0.000245584749831182"
        iyz="3.01080240182646E-08"
        izz="0.000226676365115679" />
    </inertial>
    <visual>
      <origin
        xyz="0 0 0"
        rpy="0 0 0" />
      <geometry>
        <mesh
          filename="package://hopper_cmg/meshes/Link 2.STL" />
      </geometry>
      <material
        name="">
        <color
          rgba="0.898039215686275 0.898039215686275 0.898039215686275 1" />
      </material>
    </visual>
    <collision>
      <origin
        xyz="0 0 0"
        rpy="0 0 0" />
      <geometry>
        <mesh
          filename="package://hopper_cmg/meshes/Link 2.STL" />
      </geometry>
    </collision>
  </link>
  <joint
    name="Joint 2"
    type="revolute">
    <origin
      xyz="0 0 0"
      rpy="3.14159265358979 0.553232742319403 -3.14159265358979" />
    <parent
      link="base_link" />
    <child
      link="Link 2" />
    <axis
      xyz="0 -1 0" />
    <limit
      lower="-3.14"
      upper="3.14"
      effort="0"
      velocity="0" />
  </joint>
  <link
    name="Link 3">
    <inertial>
      <origin
        xyz="0.101438171272256 -0.00251001084087024 -0.014853285679165"
        rpy="0 0 0" />
      <mass
        value="0.124857602987161" />
      <inertia
        ixx="1.6074253426557E-05"
        ixy="-5.546065674457E-07"
        ixz="1.00368287669173E-06"
        iyy="0.000116506435095087"
        iyz="1.07130834491584E-07"
        izz="0.000112946753591596" />
    </inertial>
    <visual>
      <origin
        xyz="0 0 0"
        rpy="0 0 0" />
      <geometry>
        <mesh
          filename="package://hopper_cmg/meshes/Link 3.STL" />
      </geometry>
      <material
        name="">
        <color
          rgba="1 1 1 1" />
      </material>
    </visual>
    <collision>
      <origin
        xyz="0 0 0"
        rpy="0 0 0" />
      <geometry>
        <mesh
          filename="package://hopper_cmg/meshes/Link 3.STL" />
      </geometry>
    </collision>
  </link>
  <joint
    name="Joint 3"
    type="revolute">
    <origin
      xyz="0.270000000042219 0 0"
      rpy="-3.14159265358979 -1.07683151743819 3.14159265358979" />
    <parent
      link="Link 2" />
    <child
      link="Link 3" />
    <axis
      xyz="0 -1 0" />
    <limit
      lower="-1.8295"
      upper="0.7597"
      effort="0"
      velocity="0" />
  </joint>
  <link
    name="gimbal0">
    <inertial>
      <origin
        xyz="-3.24439967699375E-05 -0.00476693417491843 -0.0330147004711936"
        rpy="0 0 0" />
      <mass
        value="0.145059153810549" />
      <inertia
        ixx="2.16270334418995E-05"
        ixy="-3.51124299812495E-08"
        ixz="-1.74609413518481E-09"
        iyy="2.68084572591951E-05"
        iyz="-1.59653002770007E-08"
        izz="1.56100554784467E-05" />
    </inertial>
    <visual>
      <origin
        xyz="0 0 0"
        rpy="0 0 0" />
      <geometry>
        <mesh
          filename="package://hopper_cmg/meshes/gimbal0.STL" />
      </geometry>
      <material
        name="">
        <color
          rgba="0.898039215686275 0.917647058823529 0.929411764705882 1" />
      </material>
    </visual>
    <collision>
      <origin
        xyz="0 0 0"
        rpy="0 0 0" />
      <geometry>
        <mesh
          filename="package://hopper_cmg/meshes/gimbal0.STL" />
      </geometry>
    </collision>
  </link>
  <joint
    name="joint_gimbal0"
    type="revolute">
    <origin
      xyz="0.0434163563648536 -0.166840533778391 0.047"
      rpy="1.5707963267949 0 0.785398163397444" />
    <parent
      link="base_link" />
    <child
      link="gimbal0" />
    <axis
      xyz="0 0 1" />
    <limit
      lower="0"
      upper="0"
      effort="0"
      velocity="0" />
  </joint>
  <link
    name="rw0">
    <inertial>
      <origin
        xyz="9.47886189019143E-08 -1.24203106049992E-07 -0.00582396171800516"
        rpy="0 0 0" />
      <mass
        value="0.109706994641609" />
      <inertia
        ixx="9.95338627754692E-05"
        ixy="1.3895571802408E-12"
        ixz="-7.31886554489886E-11"
        iyy="9.95339311647889E-05"
        iyz="8.72494565324636E-11"
        izz="0.000195642439396555" />
    </inertial>
    <visual>
      <origin
        xyz="0 0 0"
        rpy="0 0 0" />
      <geometry>
        <mesh
          filename="package://hopper_cmg/meshes/rw0.STL" />
      </geometry>
      <material
        name="">
        <color
          rgba="0.647058823529412 0.619607843137255 0.588235294117647 1" />
      </material>
    </visual>
    <collision>
      <origin
        xyz="0 0 0"
        rpy="0 0 0" />
      <geometry>
        <mesh
          filename="package://hopper_cmg/meshes/rw0.STL" />
      </geometry>
    </collision>
  </link>
  <joint
    name="joint_rw0"
    type="continuous">
    <origin
      xyz="0 0.0157238798738165 -0.033"
      rpy="1.5707963267949 0.73592271139374 3.14159265358979" />
    <parent
      link="gimbal0" />
    <child
      link="rw0" />
    <axis
      xyz="0 0 -1" />
  </joint>
  <link
    name="gimbal1">
    <inertial>
      <origin
        xyz="-3.4113050815722E-05 -0.0047669345728021 -0.032989749189664"
        rpy="0 0 0" />
      <mass
        value="0.145059160959022" />
      <inertia
        ixx="2.16762455646179E-05"
        ixy="-3.69555052597995E-08"
        ixz="5.81578374244778E-08"
        iyy="2.6808460074062E-05"
        iyz="1.10520369083825E-08"
        izz="1.5560847336979E-05" />
    </inertial>
    <visual>
      <origin
        xyz="0 0 0"
        rpy="0 0 0" />
      <geometry>
        <mesh
          filename="package://hopper_cmg/meshes/gimbal1.STL" />
      </geometry>
      <material
        name="">
        <color
          rgba="0.898039215686275 0.917647058823529 0.929411764705882 1" />
      </material>
    </visual>
    <collision>
      <origin
        xyz="0 0 0"
        rpy="0 0 0" />
      <geometry>
        <mesh
          filename="package://hopper_cmg/meshes/gimbal1.STL" />
      </geometry>
    </collision>
  </link>
  <joint
    name="joint_gimbal1"
    type="revolute">
    <origin
      xyz="0.12827 -0.081988 0.047"
      rpy="1.5708 0 0.7854" />
    <parent
      link="base_link" />
    <child
      link="gimbal1" />
    <axis
      xyz="0 0 1" />
    <limit
      lower="-1.57"
      upper="1.57"
      effort="0"
      velocity="0" />
  </joint>
  <link
    name="rw1">
    <inertial>
      <origin
        xyz="1.24203105980603E-07 9.47886189400782E-08 -0.00582396171800517"
        rpy="0 0 0" />
      <mass
        value="0.109706994641609" />
      <inertia
        ixx="9.95339311647886E-05"
        ixy="-1.38955724165069E-12"
        ixz="-8.72494565091135E-11"
        iyy="9.95338627754689E-05"
        iyz="-7.31886554552723E-11"
        izz="0.000195642439396555" />
    </inertial>
    <visual>
      <origin
        xyz="0 0 0"
        rpy="0 0 0" />
      <geometry>
        <mesh
          filename="package://hopper_cmg/meshes/rw1.STL" />
      </geometry>
      <material
        name="">
        <color
          rgba="0.647058823529412 0.619607843137255 0.588235294117647 1" />
      </material>
    </visual>
    <collision>
      <origin
        xyz="0 0 0"
        rpy="0 0 0" />
      <geometry>
        <mesh
          filename="package://hopper_cmg/meshes/rw1.STL" />
      </geometry>
    </collision>
  </link>
  <joint
    name="joint_rw1"
    type="continuous">
    <origin
      xyz="0 0.0157238798738165 -0.033"
      rpy="-1.57079632679489 1.55219801879299 0" />
    <parent
      link="gimbal1" />
    <child
      link="rw1" />
    <axis
      xyz="0 0 -1" />
  </joint>
  <link
    name="rwz">
    <inertial>
      <origin
        xyz="9.0534275284937E-09 -3.16385466436753E-10 -0.0146079871766001"
        rpy="0 0 0" />
      <mass
        value="0.377854494953543" />
      <inertia
        ixx="0.000300958121757204"
        ixy="-4.23471739445513E-12"
        ixz="-6.67153439557392E-12"
        iyy="0.000300957997312783"
        iyz="9.55842482003147E-14"
        izz="0.000578115934214616" />
    </inertial>
    <visual>
      <origin
        xyz="0 0 0"
        rpy="0 0 0" />
      <geometry>
        <mesh
          filename="package://hopper_cmg/meshes/rwz.STL" />
      </geometry>
      <material
        name="">
        <color
          rgba="0.647058823529412 0.619607843137255 0.588235294117647 1" />
      </material>
    </visual>
    <collision>
      <origin
        xyz="0 0 0"
        rpy="0 0 0" />
      <geometry>
        <mesh
          filename="package://hopper_cmg/meshes/rwz.STL" />
      </geometry>
    </collision>
  </link>
  <joint
    name="joint_rwz"
    type="continuous">
    <origin
      xyz="-0.076 0 0.0991000000000001"
      rpy="0 0 -2.35619449019233" />
    <parent
      link="base_link" />
    <child
      link="rwz" />
    <axis
      xyz="0 0 1" />
  </joint>
  <link
    name="gimbal2">
    <inertial>
      <origin
        xyz="-3.24439967679946E-05 -0.00476693417491841 -0.0330147004711915"
        rpy="0 0 0" />
      <mass
        value="0.14505915381055" />
      <inertia
        ixx="2.16270334418995E-05"
        ixy="-3.51124299812684E-08"
        ixz="-1.74609413519074E-09"
        iyy="2.68084572591952E-05"
        iyz="-1.59653002770028E-08"
        izz="1.56100554784468E-05" />
    </inertial>
    <visual>
      <origin
        xyz="0 0 0"
        rpy="0 0 0" />
      <geometry>
        <mesh
          filename="package://hopper_cmg/meshes/gimbal2.STL" />
      </geometry>
      <material
        name="">
        <color
          rgba="0.898039215686275 0.917647058823529 0.929411764705882 1" />
      </material>
    </visual>
    <collision>
      <origin
        xyz="0 0 0"
        rpy="0 0 0" />
      <geometry>
        <mesh
          filename="package://hopper_cmg/meshes/gimbal2.STL" />
      </geometry>
    </collision>
  </link>
  <joint
    name="joint_gimbal2"
    type="revolute">
    <origin
      xyz="0.12827 0.081988 0.047"
      rpy="1.5708 0 2.3562" />
    <parent
      link="base_link" />
    <child
      link="gimbal2" />
    <axis
      xyz="0 0 1" />
    <limit
      lower="-1.57"
      upper="1.57"
      effort="0"
      velocity="0" />
  </joint>
  <link
    name="rw2">
    <inertial>
      <origin
        xyz="9.47886189192615E-08 -1.24203106063869E-07 -0.00582396171800513"
        rpy="0 0 0" />
      <mass
        value="0.109706994641609" />
      <inertia
        ixx="9.95338627754697E-05"
        ixy="1.3895571802408E-12"
        ixz="-7.31886554593309E-11"
        iyy="9.95339311647895E-05"
        iyz="8.72494565352559E-11"
        izz="0.000195642439396556" />
    </inertial>
    <visual>
      <origin
        xyz="0 0 0"
        rpy="0 0 0" />
      <geometry>
        <mesh
          filename="package://hopper_cmg/meshes/rw2.STL" />
      </geometry>
      <material
        name="">
        <color
          rgba="0.647058823529412 0.619607843137255 0.588235294117647 1" />
      </material>
    </visual>
    <collision>
      <origin
        xyz="0 0 0"
        rpy="0 0 0" />
      <geometry>
        <mesh
          filename="package://hopper_cmg/meshes/rw2.STL" />
      </geometry>
    </collision>
  </link>
  <joint
    name="joint_rw2"
    type="continuous">
    <origin
      xyz="0 0.0157238798738165 -0.0329999999999979"
      rpy="1.5707963267949 0.73592271139374 3.14159265358979" />
    <parent
      link="gimbal2" />
    <child
      link="rw2" />
    <axis
      xyz="0 0 -1" />
  </joint>
  <link
    name="gimbal3">
    <inertial>
      <origin
        xyz="-3.41130091143782E-05 -0.00476693456543523 -0.03298974918902"
        rpy="0 0 0" />
      <mass
        value="0.145059160100867" />
      <inertia
        ixx="2.16762455706335E-05"
        ixy="-3.69554946688803E-08"
        ixz="5.81578377267653E-08"
        iyy="2.68084600312876E-05"
        iyz="1.10520332051451E-08"
        izz="1.55608472953775E-05" />
    </inertial>
    <visual>
      <origin
        xyz="0 0 0"
        rpy="0 0 0" />
      <geometry>
        <mesh
          filename="package://hopper_cmg/meshes/gimbal3.STL" />
      </geometry>
      <material
        name="">
        <color
          rgba="0.898039215686275 0.917647058823529 0.929411764705882 1" />
      </material>
    </visual>
    <collision>
      <origin
        xyz="0 0 0"
        rpy="0 0 0" />
      <geometry>
        <mesh
          filename="package://hopper_cmg/meshes/gimbal3.STL" />
      </geometry>
    </collision>
  </link>
  <joint
    name="joint_gimbal3"
    type="revolute">
    <origin
      xyz="0.043416 0.16684 0.047"
      rpy="1.5708 0 2.3562" />
    <parent
      link="base_link" />
    <child
      link="gimbal3" />
    <axis
      xyz="0 0 1" />
    <limit
      lower="-1.57"
      upper="1.57"
      effort="0"
      velocity="0" />
  </joint>
  <link
    name="rw3">
    <inertial>
      <origin
        xyz="1.2420310599448E-07 9.47886189817115E-08 -0.00582396171800516"
        rpy="0 0 0" />
      <mass
        value="0.109706994641609" />
      <inertia
        ixx="9.95339311647888E-05"
        ixy="-1.38955725181508E-12"
        ixz="-8.72494565114555E-11"
        iyy="9.95338627754691E-05"
        iyz="-7.31886554634405E-11"
        izz="0.000195642439396555" />
    </inertial>
    <visual>
      <origin
        xyz="0 0 0"
        rpy="0 0 0" />
      <geometry>
        <mesh
          filename="package://hopper_cmg/meshes/rw3.STL" />
      </geometry>
      <material
        name="">
        <color
          rgba="0.898039215686275 0.898039215686275 0.898039215686275 1" />
      </material>
    </visual>
    <collision>
      <origin
        xyz="0 0 0"
        rpy="0 0 0" />
      <geometry>
        <mesh
          filename="package://hopper_cmg/meshes/rw3.STL" />
      </geometry>
    </collision>
  </link>
  <joint
    name="joint_rw3"
    type="continuous">
    <origin
      xyz="0 0.0157238798738165 -0.033"
      rpy="-1.57079632679489 1.55219801879299 0" />
    <parent
      link="gimbal3" />
    <child
      link="rw3" />
    <axis
      xyz="0 0 -1" />
  </joint>
</robot>