<?xml version="1.0" encoding="utf-8"?>
<!-- This URDF was automatically created by SolidWorks to URDF Exporter! Originally created by Stephen Brawner (brawner@gmail.com) 
     Commit Version: 1.6.0-4-g7f85cfe  Build Version: 1.6.7995.38578
     For more information, please see http://wiki.ros.org/sw_urdf_exporter -->
<robot
  name="hopper_cmg">
  <link
    name="base_link">
    <inertial>
      <origin
        xyz="0.00261236312175525 0.000103468861548215 0.0225006879754611"
        rpy="0 0 0" />
      <mass
        value="4.33217212044982" />
      <inertia
        ixx="0.00375815397665309"
        ixy="-3.2239869383998E-06"
        ixz="5.54302905238984E-05"
        iyy="0.00602760648024936"
        iyz="8.3576326935109E-06"
        izz="0.00485347607828344" />
    </inertial>
    <visual>
      <origin
        xyz="0 0 0"
        rpy="0 0 0" />
      <geometry>
        <mesh
          filename="package://hopper_cmg/meshes/base_link.STL" />
      </geometry>
      <material
        name="">
        <color
          rgba="0.898039215686275 0.898039215686275 0.898039215686275 1" />
      </material>
    </visual>
    <collision>
      <origin
        xyz="0 0 0"
        rpy="0 0 0" />
      <geometry>
        <mesh
          filename="package://hopper_cmg/meshes/base_link.STL" />
      </geometry>
    </collision>
  </link>
  <link
    name="Link 0">
    <inertial>
      <origin
        xyz="0.0121851264299084 0.018088901394185 0.00112690392742547"
        rpy="0 0 0" />
      <mass
        value="0.256385566503952" />
      <inertia
        ixx="3.84650100874964E-05"
        ixy="1.5379784060096E-05"
        ixz="-8.48318798628565E-06"
        iyy="0.00017263374747093"
        iyz="1.08260201375488E-06"
        izz="0.000148822440720501" />
    </inertial>
    <visual>
      <origin
        xyz="0 0 0"
        rpy="0 0 0" />
      <geometry>
        <mesh
          filename="package://hopper_cmg/meshes/Link 0.STL" />
      </geometry>
      <material
        name="">
        <color
          rgba="0.898039215686275 0.898039215686275 0.898039215686275 1" />
      </material>
    </visual>
    <collision>
      <origin
        xyz="0 0 0"
        rpy="0 0 0" />
      <geometry>
        <mesh
          filename="package://hopper_cmg/meshes/Link 0.STL" />
      </geometry>
    </collision>
  </link>
  <joint
    name="Joint 0"
    type="revolute">
    <origin
      xyz="0 0 0"
      rpy="0 0.5235987755983 0" />
    <parent
      link="base_link" />
    <child
      link="Link 0" />
    <axis
      xyz="0 -1 0" />
    <limit
      lower="-3.14"
      upper="3.14"
      effort="0"
      velocity="0" />
  </joint>
  <link
    name="Link 1">
    <inertial>
      <origin
        xyz="0.133101645966311 0.00652998365272028 -1.77401536516353E-09"
        rpy="0 0 0" />
      <mass
        value="0.0631473819780702" />
      <inertia
        ixx="2.55548531328563E-06"
        ixy="6.97718053350335E-12"
        ixz="-1.43600150329273E-12"
        iyy="0.000104301911822778"
        iyz="7.22908067835144E-12"
        izz="0.000104301119173831" />
    </inertial>
    <visual>
      <origin
        xyz="0 0 0"
        rpy="0 0 0" />
      <geometry>
        <mesh
          filename="package://hopper_cmg/meshes/Link 1.STL" />
      </geometry>
      <material
        name="">
        <color
          rgba="0.776470588235294 0.756862745098039 0.737254901960784 1" />
      </material>
    </visual>
    <collision>
      <origin
        xyz="0 0 0"
        rpy="0 0 0" />
      <geometry>
        <mesh
          filename="package://hopper_cmg/meshes/Link 1.STL" />
      </geometry>
    </collision>
  </link>
  <joint
    name="Joint 1"
    type="revolute">
    <origin
      xyz="0.0999999999999999 0 0"
      rpy="-3.14159265358979 1.0768315178335 -3.14159265358979" />
    <parent
      link="Link 0" />
    <child
      link="Link 1" />
    <axis
      xyz="0 -1 0" />
    <limit
      lower="-0.7597"
      upper="1.8295"
      effort="0"
      velocity="0" />
  </joint>
  <link
    name="Link 2">
    <inertial>
      <origin
        xyz="0.0389032293637952 -0.0169313660252965 -0.000627148519961433"
        rpy="0 0 0" />
      <mass
        value="0.288845046277886" />
      <inertia
        ixx="3.46488303623414E-05"
        ixy="-3.25958928897371E-07"
        ixz="5.24928685528964E-06"
        iyy="0.000245584747760095"
        iyz="3.01080375580466E-08"
        izz="0.000226676363063251" />
    </inertial>
    <visual>
      <origin
        xyz="0 0 0"
        rpy="0 0 0" />
      <geometry>
        <mesh
          filename="package://hopper_cmg/meshes/Link 2.STL" />
      </geometry>
      <material
        name="">
        <color
          rgba="0.898039215686275 0.898039215686275 0.898039215686275 1" />
      </material>
    </visual>
    <collision>
      <origin
        xyz="0 0 0"
        rpy="0 0 0" />
      <geometry>
        <mesh
          filename="package://hopper_cmg/meshes/Link 2.STL" />
      </geometry>
    </collision>
  </link>
  <joint
    name="Joint 2"
    type="revolute">
    <origin
      xyz="0 0 0"
      rpy="3.14159265358979 0.553232742319403 -3.14159265358979" />
    <parent
      link="base_link" />
    <child
      link="Link 2" />
    <axis
      xyz="0 -1 0" />
    <limit
      lower="-3.14"
      upper="3.14"
      effort="0"
      velocity="0" />
  </joint>
  <link
    name="Link 3">
    <inertial>
      <origin
        xyz="0.101438167926632 -0.00251001113256176 -0.0148532860390855"
        rpy="0 0 0" />
      <mass
        value="0.124857600224648" />
      <inertia
        ixx="1.60742533954399E-05"
        ixy="-5.54606838016785E-07"
        ixz="1.00368207076053E-06"
        iyy="0.000116506433929229"
        iyz="1.07131225835552E-07"
        izz="0.000112946753637288" />
    </inertial>
    <visual>
      <origin
        xyz="0 0 0"
        rpy="0 0 0" />
      <geometry>
        <mesh
          filename="package://hopper_cmg/meshes/Link 3.STL" />
      </geometry>
      <material
        name="">
        <color
          rgba="1 1 1 1" />
      </material>
    </visual>
    <collision>
      <origin
        xyz="0 0 0"
        rpy="0 0 0" />
      <geometry>
        <mesh
          filename="package://hopper_cmg/meshes/Link 3.STL" />
      </geometry>
    </collision>
  </link>
  <joint
    name="Joint 3"
    type="revolute">
    <origin
      xyz="0.270000000042219 0 0"
      rpy="-3.14159265358979 -1.07683151743819 3.14159265358979" />
    <parent
      link="Link 2" />
    <child
      link="Link 3" />
    <axis
      xyz="0 -1 0" />
    <limit
      lower="-1.8295"
      upper="0.7597"
      effort="0"
      velocity="0" />
  </joint>
  <link
    name="gimbal0">
    <inertial>
      <origin
        xyz="-3.24439967725743E-05 -0.00476693417491671 -1.47004711921472E-05"
        rpy="0 0 0" />
      <mass
        value="0.145059153810549" />
      <inertia
        ixx="2.16270334418995E-05"
        ixy="-3.51124299812523E-08"
        ixz="-1.74609413518227E-09"
        iyy="2.68084572591951E-05"
        iyz="-1.59653002770006E-08"
        izz="1.56100554784467E-05" />
    </inertial>
    <visual>
      <origin
        xyz="0 0 0"
        rpy="0 0 0" />
      <geometry>
        <mesh
          filename="package://hopper_cmg/meshes/gimbal0.STL" />
      </geometry>
      <material
        name="">
        <color
          rgba="0.898039215686275 0.917647058823529 0.929411764705882 1" />
      </material>
    </visual>
    <collision>
      <origin
        xyz="0 0 0"
        rpy="0 0 0" />
      <geometry>
        <mesh
          filename="package://hopper_cmg/meshes/gimbal0.STL" />
      </geometry>
    </collision>
  </link>
  <joint
    name="joint_gimbal0"
    type="revolute">
    <origin
      xyz="0.020082 -0.14351 0.047"
      rpy="1.5708 0 0.7854" />
    <parent
      link="base_link" />
    <child
      link="gimbal0" />
    <axis
      xyz="0 0 1" />
    <limit
      lower="0"
      upper="0"
      effort="0"
      velocity="0" />
  </joint>
  <link
    name="rw0">
    <inertial>
      <origin
        xyz="-1.37939488192851E-07 -0.0094592721093547 -1.05271875980306E-07"
        rpy="0 0 0" />
      <mass
        value="0.0987820774247236" />
      <inertia
        ixx="5.92329023873011E-05"
        ixy="-8.72494565394251E-11"
        ixz="-1.38955719548739E-12"
        iyy="0.000115069019848817"
        iyz="-7.31886554523282E-11"
        izz="5.92328339979814E-05" />
    </inertial>
    <visual>
      <origin
        xyz="0 0 0"
        rpy="0 0 0" />
      <geometry>
        <mesh
          filename="package://hopper_cmg/meshes/rw0.STL" />
      </geometry>
      <material
        name="">
        <color
          rgba="0.647058823529412 0.619607843137255 0.588235294117647 1" />
      </material>
    </visual>
    <collision>
      <origin
        xyz="0 0 0"
        rpy="0 0 0" />
      <geometry>
        <mesh
          filename="package://hopper_cmg/meshes/rw0.STL" />
      </geometry>
    </collision>
  </link>
  <joint
    name="joint_rw0"
    type="continuous">
    <origin
      xyz="0 0 0"
      rpy="0 -0.834873615401156 3.14159265358979" />
    <parent
      link="gimbal0" />
    <child
      link="rw0" />
    <axis
      xyz="0 1 0" />
  </joint>
  <link
    name="gimbal1">
    <inertial>
      <origin
        xyz="-3.41130508183726E-05 -0.00476693457280038 1.02508103375226E-05"
        rpy="0 0 0" />
      <mass
        value="0.145059160959022" />
      <inertia
        ixx="2.16762455646179E-05"
        ixy="-3.69555052598017E-08"
        ixz="5.8157837424477E-08"
        iyy="2.6808460074062E-05"
        iyz="1.10520369083828E-08"
        izz="1.5560847336979E-05" />
    </inertial>
    <visual>
      <origin
        xyz="0 0 0"
        rpy="0 0 0" />
      <geometry>
        <mesh
          filename="package://hopper_cmg/meshes/gimbal1.STL" />
      </geometry>
      <material
        name="">
        <color
          rgba="0.898039215686275 0.917647058823529 0.929411764705882 1" />
      </material>
    </visual>
    <collision>
      <origin
        xyz="0 0 0"
        rpy="0 0 0" />
      <geometry>
        <mesh
          filename="package://hopper_cmg/meshes/gimbal1.STL" />
      </geometry>
    </collision>
  </link>
  <joint
    name="joint_gimbal1"
    type="revolute">
    <origin
      xyz="0.10493 -0.058653 0.047"
      rpy="1.5708 0 0.7854" />
    <parent
      link="base_link" />
    <child
      link="gimbal1" />
    <axis
      xyz="0 0 1" />
    <limit
      lower="0"
      upper="0"
      effort="0"
      velocity="0" />
  </joint>
  <link
    name="rw1">
    <inertial>
      <origin
        xyz="1.05271877680335E-07 -0.00945927210935471 -1.37939489469607E-07"
        rpy="0 0 0" />
      <mass
        value="0.0987820774247234" />
      <inertia
        ixx="5.92328339979811E-05"
        ixy="7.31886554478036E-11"
        ixz="1.38955723656849E-12"
        iyy="0.000115069019848817"
        iyz="-8.7249456524772E-11"
        izz="5.92329023873008E-05" />
    </inertial>
    <visual>
      <origin
        xyz="0 0 0"
        rpy="0 0 0" />
      <geometry>
        <mesh
          filename="package://hopper_cmg/meshes/rw1.STL" />
      </geometry>
      <material
        name="">
        <color
          rgba="0.647058823529412 0.619607843137255 0.588235294117647 1" />
      </material>
    </visual>
    <collision>
      <origin
        xyz="0 0 0"
        rpy="0 0 0" />
      <geometry>
        <mesh
          filename="package://hopper_cmg/meshes/rw1.STL" />
      </geometry>
    </collision>
  </link>
  <joint
    name="joint_rw1"
    type="continuous">
    <origin
      xyz="0 0 0"
      rpy="0 0.0185983080019021 3.14159265358979" />
    <parent
      link="gimbal1" />
    <child
      link="rw1" />
    <axis
      xyz="0 1 0" />
  </joint>
  <link
    name="rwz">
    <inertial>
      <origin
        xyz="9.05342958934519E-09 -3.16383627629868E-10 -0.0146079871766004"
        rpy="0 0 0" />
      <mass
        value="0.377854494953542" />
      <inertia
        ixx="0.000300958121757204"
        ixy="-4.23471723182481E-12"
        ixz="-6.67153440779162E-12"
        iyy="0.000300957997312783"
        iyz="9.55842525963388E-14"
        izz="0.000578115934214615" />
    </inertial>
    <visual>
      <origin
        xyz="0 0 0"
        rpy="0 0 0" />
      <geometry>
        <mesh
          filename="package://hopper_cmg/meshes/rwz.STL" />
      </geometry>
      <material
        name="">
        <color
          rgba="0.647058823529412 0.619607843137255 0.588235294117647 1" />
      </material>
    </visual>
    <collision>
      <origin
        xyz="0 0 0"
        rpy="0 0 0" />
      <geometry>
        <mesh
          filename="package://hopper_cmg/meshes/rwz.STL" />
      </geometry>
    </collision>
  </link>
  <joint
    name="joint_rwz"
    type="continuous">
    <origin
      xyz="-0.076 0 0.0991"
      rpy="0 0 -2.3562" />
    <parent
      link="base_link" />
    <child
      link="rwz" />
    <axis
      xyz="0 0 1" />
  </joint>
  <link
    name="gimbal2">
    <inertial>
      <origin
        xyz="-3.24439967680501E-05 -0.00476693417491845 -1.47004711914533E-05"
        rpy="0 0 0" />
      <mass
        value="0.145059153810549" />
      <inertia
        ixx="2.16270334418995E-05"
        ixy="-3.51124299812618E-08"
        ixz="-1.74609413517719E-09"
        iyy="2.68084572591951E-05"
        iyz="-1.59653002770088E-08"
        izz="1.56100554784467E-05" />
    </inertial>
    <visual>
      <origin
        xyz="0 0 0"
        rpy="0 0 0" />
      <geometry>
        <mesh
          filename="package://hopper_cmg/meshes/gimbal2.STL" />
      </geometry>
      <material
        name="">
        <color
          rgba="0.898039215686275 0.917647058823529 0.929411764705882 1" />
      </material>
    </visual>
    <collision>
      <origin
        xyz="0 0 0"
        rpy="0 0 0" />
      <geometry>
        <mesh
          filename="package://hopper_cmg/meshes/gimbal2.STL" />
      </geometry>
    </collision>
  </link>
  <joint
    name="joint_gimbal2"
    type="revolute">
    <origin
      xyz="0.10493 0.058653 0.047"
      rpy="1.5708 0 2.3562" />
    <parent
      link="base_link" />
    <child
      link="gimbal2" />
    <axis
      xyz="0 0 1" />
    <limit
      lower="0"
      upper="0"
      effort="0"
      velocity="0" />
  </joint>
  <link
    name="rw2">
    <inertial>
      <origin
        xyz="-1.37939490787997E-07 -0.00945927210935298 -1.05271872420654E-07"
        rpy="0 0 0" />
      <mass
        value="0.0987820774247233" />
      <inertia
        ixx="5.92329023873009E-05"
        ixy="-8.72494564478895E-11"
        ixz="-1.38955719591091E-12"
        iyy="0.000115069019848817"
        iyz="-7.31886539007135E-11"
        izz="5.92328339979812E-05" />
    </inertial>
    <visual>
      <origin
        xyz="0 0 0"
        rpy="0 0 0" />
      <geometry>
        <mesh
          filename="package://hopper_cmg/meshes/rw2.STL" />
      </geometry>
      <material
        name="">
        <color
          rgba="0.647058823529412 0.619607843137255 0.588235294117647 1" />
      </material>
    </visual>
    <collision>
      <origin
        xyz="0 0 0"
        rpy="0 0 0" />
      <geometry>
        <mesh
          filename="package://hopper_cmg/meshes/rw2.STL" />
      </geometry>
    </collision>
  </link>
  <joint
    name="joint_rw2"
    type="continuous">
    <origin
      xyz="0 0 0"
      rpy="0 -0.834873615401156 3.14159265358979" />
    <parent
      link="gimbal2" />
    <child
      link="rw2" />
    <axis
      xyz="0 1 0" />
  </joint>
  <link
    name="gimbal3">
    <inertial>
      <origin
        xyz="-3.41130091143643E-05 -0.00476693456543522 1.02508109800087E-05"
        rpy="0 0 0" />
      <mass
        value="0.145059160100868" />
      <inertia
        ixx="2.16762455706335E-05"
        ixy="-3.69554946688773E-08"
        ixz="5.81578377267636E-08"
        iyy="2.68084600312876E-05"
        iyz="1.10520332051307E-08"
        izz="1.55608472953775E-05" />
    </inertial>
    <visual>
      <origin
        xyz="0 0 0"
        rpy="0 0 0" />
      <geometry>
        <mesh
          filename="package://hopper_cmg/meshes/gimbal3.STL" />
      </geometry>
      <material
        name="">
        <color
          rgba="0.898039215686275 0.917647058823529 0.929411764705882 1" />
      </material>
    </visual>
    <collision>
      <origin
        xyz="0 0 0"
        rpy="0 0 0" />
      <geometry>
        <mesh
          filename="package://hopper_cmg/meshes/gimbal3.STL" />
      </geometry>
    </collision>
  </link>
  <joint
    name="joint_gimbal3"
    type="revolute">
    <origin
      xyz="0.020082 0.14351 0.047"
      rpy="1.5708 0 2.3562" />
    <parent
      link="base_link" />
    <child
      link="gimbal3" />
    <axis
      xyz="0 0 1" />
    <limit
      lower="0"
      upper="0"
      effort="0"
      velocity="0" />
  </joint>
  <link
    name="rw3">
    <inertial>
      <origin
        xyz="0.009459272109353 1.05271875036617E-07 -1.37939491051675E-07"
        rpy="0 0 0" />
      <mass
        value="0.0987820774247234" />
      <inertia
        ixx="0.000115069019848817"
        ixy="-7.31886555445165E-11"
        ixz="8.72494564435104E-11"
        iyy="5.92328339979811E-05"
        iyz="1.3895572213219E-12"
        izz="5.92329023873008E-05" />
    </inertial>
    <visual>
      <origin
        xyz="0 0 0"
        rpy="0 0 0" />
      <geometry>
        <mesh
          filename="package://hopper_cmg/meshes/rw3.STL" />
      </geometry>
      <material
        name="">
        <color
          rgba="0.898039215686275 0.898039215686275 0.898039215686275 1" />
      </material>
    </visual>
    <collision>
      <origin
        xyz="0 0 0"
        rpy="0 0 0" />
      <geometry>
        <mesh
          filename="package://hopper_cmg/meshes/rw3.STL" />
      </geometry>
    </collision>
  </link>
  <joint
    name="joint_rw3"
    type="continuous">
    <origin
      xyz="0 0 0"
      rpy="-0.018598 0 1.5708" />
    <parent
      link="gimbal3" />
    <child
      link="rw3" />
    <axis
      xyz="-1 0 0" />
  </joint>
</robot>