<?xml version="1.0" encoding="utf-8"?>
<!-- This URDF was automatically created by SolidWorks to URDF Exporter! Originally created by Stephen Brawner (brawner@gmail.com) 
     Commit Version: 1.5.1-0-g916b5db  Build Version: 1.5.7152.31018
     For more information, please see http://wiki.ros.org/sw_urdf_exporter -->
<robot
  name="flyhopper_mockup">
  <link
    name="base_link">
    <inertial>
      <origin
        xyz="2.9532E-21 -5.2832E-18 -6.047E-34"
        rpy="0 0 0" />
      <mass
        value="10" />
      <inertia
        ixx="0.016546"
        ixy="8.3198E-20"
        ixz="-1.2693E-24"
        iyy="0.016752"
        iyz="-2.8518E-21"
        izz="0.016546" />
    </inertial>
    <visual>
      <origin
        xyz="0 0 0"
        rpy="0 0 0" />
      <geometry>
        <mesh
          filename="../../res/flyhopper_mockup/meshes/base_link.stl" />  # package://../res/flyhopper_mockup/meshes/base_link.stl
      </geometry>
      <material
        name="">
        <color
          rgba="0.79216 0.81961 0.93333 1" />
      </material>
    </visual>
    <collision>
      <origin
        xyz="0 0 0"
        rpy="0 0 0" />
      <geometry>
        <mesh
          filename="../../res/flyhopper_mockup/meshes/base_link.stl" />  # package://../res/flyhopper_mockup/meshes/base_link.stl
      </geometry>
    </collision>
  </link>
  <link
    name="Link 1">
    <inertial>
      <origin
        xyz="0.15 -6.7782E-19 2.7756E-17"
        rpy="0 0 0" />
      <mass
        value="0.1" />
      <inertia
        ixx="0.00022795"
        ixy="7.5734E-20"
        ixz="1.0164E-19"
        iyy="0.0064827"
        iyz="-2.4255E-20"
        izz="0.0063485" />
    </inertial>
    <visual>
      <origin
        xyz="0 0 0"
        rpy="0 0 0" />
      <geometry>
        <mesh
          filename="../../src/res/flyhopper_mockup/meshes/Link 1.stl" />
      </geometry>
      <material
        name="">
        <color
          rgba="0.79216 0.81961 0.93333 1" />
      </material>
    </visual>
    <collision>
      <origin
        xyz="0 0 0"
        rpy="0 0 0" />
      <geometry>
        <mesh
          filename="../../src/res/flyhopper_mockup/meshes/Link 1.stl" />
      </geometry>
    </collision>
  </link>
  <joint
    name="Joint 1"
    type="revolute">
    <origin
      xyz="0 0 0"
      rpy="3.1416 0.5236 3.1416" />
    <parent
      link="base_link" />
    <child
      link="Link 1" />
    <axis
      xyz="0 -1 0" />
    <limit
      lower="-3.14"
      upper="3.14"
      effort="0"
      velocity="0" />
  </joint>
  <link
    name="Link 2">
    <inertial>
      <origin
        xyz="0.15 -1.7669E-17 -5.5511E-17"
        rpy="0 0 0" />
      <mass
        value="0.1" />
      <inertia
        ixx="0.00022795"
        ixy="-1.3268E-20"
        ixz="1.3417E-18"
        iyy="0.0064827"
        iyz="4.945E-20"
        izz="0.0063485" />
    </inertial>
    <visual>
      <origin
        xyz="0 0 0"
        rpy="0 0 0" />
      <geometry>
        <mesh
          filename="../../src/res/flyhopper_mockup/meshes/Link 2.stl" />
      </geometry>
      <material
        name="">
        <color
          rgba="0.79216 0.81961 0.93333 1" />
      </material>
    </visual>
    <collision>
      <origin
        xyz="0 0 0"
        rpy="0 0 0" />
      <geometry>
        <mesh
          filename="../../src/res/flyhopper_mockup/meshes/Link 2.stl" />
      </geometry>
    </collision>
  </link>
  <joint
    name="Joint 2"
    type="revolute">
    <origin
      xyz="0.3 0 0"
      rpy="3.1416 -1.0472 3.1416" />
    <parent
      link="Link 1" />
    <child
      link="Link 2" />
    <axis
      xyz="0 -1 0" />
    <limit
      lower="-3.14"
      upper="3.14"
      effort="0"
      velocity="0" />
  </joint>
</robot>