<?xml version="1.0" encoding="utf-8"?>
<!-- This URDF was automatically created by SolidWorks to URDF Exporter! Originally created by Stephen Brawner (brawner@gmail.com) 
     Commit Version: 1.5.1-0-g916b5db  Build Version: 1.5.7152.31018
     For more information, please see http://wiki.ros.org/sw_urdf_exporter -->
<robot
  name="flyhopper_rw">
  <link
    name="base_link">
    <inertial>
      <origin
        xyz="-0.00514562676486118 3.38408505325795E-06 0.047849547003391"
        rpy="0 0 0" />
      <mass
        value="3.26735928312179" />
      <inertia
        ixx="0.00379760962452026"
        ixy="5.23210526490385E-06"
        ixz="9.38257981898972E-05"
        iyy="0.0050103912671889"
        iyz="-1.39610537747668E-07"
        izz="0.00361361274132368" />
    </inertial>
    <visual>
      <origin
        xyz="0 0 0"
        rpy="0 0 0" />
      <geometry>
        <mesh
          filename="package://flyhopper_rw/meshes/base_link.STL" />
      </geometry>
      <material
        name="">
        <color
          rgba="0.898039215686275 0.898039215686275 0.898039215686275 1" />
      </material>
    </visual>
    <collision>
      <origin
        xyz="0 0 0"
        rpy="0 0 0" />
      <geometry>
        <mesh
          filename="package://flyhopper_rw/meshes/base_link.STL" />
      </geometry>
    </collision>
  </link>
  <link
    name="Link 0">
    <inertial>
      <origin
        xyz="0.0127529105137942 0.0182883330694508 0.00117942063158857"
        rpy="0 0 0" />
      <mass
        value="0.244971505585676" />
      <inertia
        ixx="3.8045173571515E-05"
        ixy="1.53797204014879E-05"
        ixz="-8.48319768329473E-06"
        iyy="0.00017256604337067"
        iyz="1.08265579708328E-06"
        izz="0.000148402608297104" />
    </inertial>
    <visual>
      <origin
        xyz="0 0 0"
        rpy="0 0 0" />
      <geometry>
        <mesh
          filename="package://flyhopper_rw/meshes/Link 0.STL" />
      </geometry>
      <material
        name="">
        <color
          rgba="0.898039215686275 0.898039215686275 0.898039215686275 1" />
      </material>
    </visual>
    <collision>
      <origin
        xyz="0 0 0"
        rpy="0 0 0" />
      <geometry>
        <mesh
          filename="package://flyhopper_rw/meshes/Link 0.STL" />
      </geometry>
    </collision>
  </link>
  <joint
    name="Joint 0"
    type="revolute">
    <origin
      xyz="0 0 0"
      rpy="0 0.367813142390011 0" />
    <parent
      link="base_link" />
    <child
      link="Link 0" />
    <axis
      xyz="0 -1 0" />
    <limit
      lower="-3.14"
      upper="3.14"
      effort="0"
      velocity="0" />
  </joint>
  <link
    name="Link 1">
    <inertial>
      <origin
        xyz="0.133412271009693 0.00656091741696295 -2.31284152940603E-09"
        rpy="0 0 0" />
      <mass
        value="0.0630003565580363" />
      <inertia
        ixx="2.55500661184467E-06"
        ixy="6.36488699417343E-12"
        ixz="-9.14129078748834E-13"
        iyy="0.000104300956197372"
        iyz="7.80257758764037E-12"
        izz="0.000104300640063782" />
    </inertial>
    <visual>
      <origin
        xyz="0 0 0"
        rpy="0 0 0" />
      <geometry>
        <mesh
          filename="package://flyhopper_rw/meshes/Link 1.STL" />
      </geometry>
      <material
        name="">
        <color
          rgba="0.776470588235294 0.756862745098039 0.737254901960784 1" />
      </material>
    </visual>
    <collision>
      <origin
        xyz="0 0 0"
        rpy="0 0 0" />
      <geometry>
        <mesh
          filename="package://flyhopper_rw/meshes/Link 1.STL" />
      </geometry>
    </collision>
  </link>
  <joint
    name="Joint 1"
    type="revolute">
    <origin
      xyz="0.1 0 0"
      rpy="-3.14159265358979 0.838668064118148 -3.14159265358979" />
    <parent
      link="Link 0" />
    <child
      link="Link 1" />
    <axis
      xyz="0 -1 0" />
    <limit
      lower="-0.7597"
      upper="1.8295"
      effort="0"
      velocity="0" />
  </joint>
  <link
    name="Link 2">
    <inertial>
      <origin
        xyz="0.041553724196661 -0.0171272810504263 -0.000857922718620643"
        rpy="0 0 0" />
      <mass
        value="0.272297541798603" />
      <inertia
        ixx="3.39636964797473E-05"
        ixy="-3.26049250362929E-07"
        ixz="5.24912410792342E-06"
        iyy="0.000245491222547539"
        iyz="3.0200680308278E-08"
        izz="0.000225991010878087" />
    </inertial>
    <visual>
      <origin
        xyz="0 0 0"
        rpy="0 0 0" />
      <geometry>
        <mesh
          filename="package://flyhopper_rw/meshes/Link 2.STL" />
      </geometry>
      <material
        name="">
        <color
          rgba="0.898039215686275 0.898039215686275 0.898039215686275 1" />
      </material>
    </visual>
    <collision>
      <origin
        xyz="0 0 0"
        rpy="0 0 0" />
      <geometry>
        <mesh
          filename="package://flyhopper_rw/meshes/Link 2.STL" />
      </geometry>
    </collision>
  </link>
  <joint
    name="Joint 2"
    type="revolute">
    <origin
      xyz="0 0 0"
      rpy="3.14159265358979 0.470854921867631 3.14159265358979" />
    <parent
      link="base_link" />
    <child
      link="Link 2" />
    <axis
      xyz="0 -1 0" />
    <limit
      lower="-3.14"
      upper="3.14"
      effort="0"
      velocity="0" />
  </joint>
  <link
    name="Link 3">
    <inertial>
      <origin
        xyz="0.099397 -0.0025532 -0.014762"
        rpy="0 0 0" />
      <mass
        value="0.12288" />
      <inertia
        ixx="1.6058E-05"
        ixy="-5.5656E-07"
        ixz="1.0036E-06"
        iyy="0.00011648"
        iyz="1.0712E-07"
        izz="0.00011292" />
    </inertial>
    <visual>
      <origin
        xyz="0 0 0"
        rpy="0 0 0" />
      <geometry>
        <mesh
          filename="package://flyhopper_rw/meshes/Link 3.STL" />
      </geometry>
      <material
        name="">
        <color
          rgba="1 1 1 1" />
      </material>
    </visual>
    <collision>
      <origin
        xyz="0 0 0"
        rpy="0 0 0" />
      <geometry>
        <mesh
          filename="package://flyhopper_rw/meshes/Link 3.STL" />
      </geometry>
    </collision>
  </link>
  <joint
    name="Joint 3"
    type="revolute">
    <origin
      xyz="0.27 0 0"
      rpy="-3.1416 -0.83867 3.1416" />
    <parent
      link="Link 2" />
    <child
      link="Link 3" />
    <axis
      xyz="0 -1 0" />
    <limit
      lower="-1.8295"
      upper="0.7597"
      effort="0"
      velocity="0" />
  </joint>
  <link
    name="rw0">
    <inertial>
      <origin
        xyz="-0.012902 -9.7145E-17 -1.249E-16"
        rpy="0 0 0" />
      <mass
        value="0.60624" />
      <inertia
        ixx="0.0019134"
        ixy="-1.6263E-19"
        ixz="1.0842E-19"
        iyy="0.00097876"
        iyz="-1.1906E-14"
        izz="0.00097876" />
    </inertial>
    <visual>
      <origin
        xyz="0 0 0"
        rpy="0 0 0" />
      <geometry>
        <mesh
          filename="package://flyhopper_rw/meshes/rw0.STL" />
      </geometry>
      <material
        name="">
        <color
          rgba="0.64706 0.61961 0.58824 1" />
      </material>
    </visual>
    <collision>
      <origin
        xyz="0 0 0"
        rpy="0 0 0" />
      <geometry>
        <mesh
          filename="package://flyhopper_rw/meshes/rw0.STL" />
      </geometry>
    </collision>
  </link>
  <joint
    name="joint_rw0"
    type="continuous">
    <origin
      xyz="0.010406 -0.10233 0.124"
      rpy="2.5708 0 -0.7854" />
    <parent
      link="base_link" />
    <child
      link="rw0" />
    <axis
      xyz="1 0 0" />
  </joint>
  <link
    name="rw1">
    <inertial>
      <origin
        xyz="-0.012902 -8.6042E-16 1.3878E-16"
        rpy="0 0 0" />
      <mass
        value="0.60624" />
      <inertia
        ixx="0.0019134"
        ixy="-1.3553E-19"
        ixz="4.0658E-20"
        iyy="0.00097876"
        iyz="1.1809E-14"
        izz="0.00097876" />
    </inertial>
    <visual>
      <origin
        xyz="0 0 0"
        rpy="0 0 0" />
      <geometry>
        <mesh
          filename="package://flyhopper_rw/meshes/rw1.STL" />
      </geometry>
      <material
        name="">
        <color
          rgba="0.64706 0.61961 0.58824 1" />
      </material>
    </visual>
    <collision>
      <origin
        xyz="0 0 0"
        rpy="0 0 0" />
      <geometry>
        <mesh
          filename="package://flyhopper_rw/meshes/rw1.STL" />
      </geometry>
    </collision>
  </link>
  <joint
    name="joint_rw1"
    type="continuous">
    <origin
      xyz="0.010406 0.10233 0.124"
      rpy="-0.30356 0 0.7854" />
    <parent
      link="base_link" />
    <child
      link="rw1" />
    <axis
      xyz="-1 0 0" />
  </joint>
</robot>