<?xml version="1.0" encoding="utf-8"?>
<!-- This URDF was automatically created by SolidWorks to URDF Exporter! Originally created by Stephen Brawner (brawner@gmail.com) 
     Commit Version: 1.5.1-0-g916b5db  Build Version: 1.5.7152.31018
     For more information, please see http://wiki.ros.org/sw_urdf_exporter -->
<robot
  name="flyhopper_rwz">
  <link
    name="base_link">
    <inertial>
      <origin
        xyz="0.00277970763371113 3.21133771858963E-06 0.0516178695133309"
        rpy="0 0 0" />
      <mass
        value="3.45555122752423" />
      <inertia
        ixx="0.00391232575184665"
        ixy="5.23017215894428E-06"
        ixz="3.91531787259724E-05"
        iyy="0.00474659484796222"
        iyz="-1.38986266493543E-07"
        izz="0.00416410479019696" />
    </inertial>
    <visual>
      <origin
        xyz="0 0 0"
        rpy="0 0 0" />
      <geometry>
        <mesh
          filename="package://flyhopper_rwz/meshes/base_link.STL" />
      </geometry>
      <material
        name="">
        <color
          rgba="0.898039215686275 0.898039215686275 0.898039215686275 1" />
      </material>
    </visual>
    <collision>
      <origin
        xyz="0 0 0"
        rpy="0 0 0" />
      <geometry>
        <mesh
          filename="package://flyhopper_rwz/meshes/base_link.STL" />
      </geometry>
    </collision>
  </link>
  <link
    name="Link 0">
    <inertial>
      <origin
        xyz="0.0127529127378812 0.0182883338723075 0.0011794212498648"
        rpy="0 0 0" />
      <mass
        value="0.244971488284729" />
      <inertia
        ixx="3.80451758513438E-05"
        ixy="1.53797221812804E-05"
        ixz="-8.48318992165916E-06"
        iyy="0.000172566032890378"
        iyz="1.08265731436023E-06"
        izz="0.000148402602231607" />
    </inertial>
    <visual>
      <origin
        xyz="0 0 0"
        rpy="0 0 0" />
      <geometry>
        <mesh
          filename="package://flyhopper_rwz/meshes/Link 0.STL" />
      </geometry>
      <material
        name="">
        <color
          rgba="0.898039215686275 0.898039215686275 0.898039215686275 1" />
      </material>
    </visual>
    <collision>
      <origin
        xyz="0 0 0"
        rpy="0 0 0" />
      <geometry>
        <mesh
          filename="package://flyhopper_rwz/meshes/Link 0.STL" />
      </geometry>
    </collision>
  </link>
  <joint
    name="Joint 0"
    type="revolute">
    <origin
      xyz="0 0 0"
      rpy="0 0.5236 0" />
    <parent
      link="base_link" />
    <child
      link="Link 0" />
    <axis
      xyz="0 -1 0" />
    <limit
      lower="-3.14"
      upper="3.14"
      effort="0"
      velocity="0" />
  </joint>
  <link
    name="Link 1">
    <inertial>
      <origin
        xyz="0.133412270784766 0.00656091735650182 -1.77815701052353E-09"
        rpy="0 0 0" />
      <mass
        value="0.0630003554418502" />
      <inertia
        ixx="2.55500637433954E-06"
        ixy="6.97717873028574E-12"
        ixz="-1.43600174617942E-12"
        iyy="0.000104300956150293"
        iyz="7.22908165182594E-12"
        izz="0.000104300640234885" />
    </inertial>
    <visual>
      <origin
        xyz="0 0 0"
        rpy="0 0 0" />
      <geometry>
        <mesh
          filename="package://flyhopper_rwz/meshes/Link 1.STL" />
      </geometry>
      <material
        name="">
        <color
          rgba="0.776470588235294 0.756862745098039 0.737254901960784 1" />
      </material>
    </visual>
    <collision>
      <origin
        xyz="0 0 0"
        rpy="0 0 0" />
      <geometry>
        <mesh
          filename="package://flyhopper_rwz/meshes/Link 1.STL" />
      </geometry>
    </collision>
  </link>
  <joint
    name="Joint 1"
    type="revolute">
    <origin
      xyz="0.1 0 0"
      rpy="3.1416 1.0768 3.1416" />
    <parent
      link="Link 0" />
    <child
      link="Link 1" />
    <axis
      xyz="0 -1 0" />
    <limit
      lower="-0.7597"
      upper="1.8295"
      effort="0"
      velocity="0" />
  </joint>
  <link
    name="Link 2">
    <inertial>
      <origin
        xyz="0.0415536743705373 -0.0171272776699121 -0.000857911925556985"
        rpy="0 0 0" />
      <mass
        value="0.272297640488147" />
      <inertia
        ixx="3.39637179166542E-05"
        ixy="-3.26027260981698E-07"
        ixz="5.24928685485485E-06"
        iyy="0.000245491496487658"
        iyz="3.02002424391176E-08"
        izz="0.000225991263249728" />
    </inertial>
    <visual>
      <origin
        xyz="0 0 0"
        rpy="0 0 0" />
      <geometry>
        <mesh
          filename="package://flyhopper_rwz/meshes/Link 2.STL" />
      </geometry>
      <material
        name="">
        <color
          rgba="0.898039215686275 0.898039215686275 0.898039215686275 1" />
      </material>
    </visual>
    <collision>
      <origin
        xyz="0 0 0"
        rpy="0 0 0" />
      <geometry>
        <mesh
          filename="package://flyhopper_rwz/meshes/Link 2.STL" />
      </geometry>
    </collision>
  </link>
  <joint
    name="Joint 2"
    type="revolute">
    <origin
      xyz="0 0 0"
      rpy="3.1416 0.55323 3.1416" />
    <parent
      link="base_link" />
    <child
      link="Link 2" />
    <axis
      xyz="0 -1 0" />
    <limit
      lower="-3.14"
      upper="3.14"
      effort="0"
      velocity="0" />
  </joint>
  <link
    name="Link 3">
    <inertial>
      <origin
        xyz="0.0993974163045883 -0.00255323603820135 -0.0147624615939491"
        rpy="0 0 0" />
      <mass
        value="0.122877254119564" />
      <inertia
        ixx="1.60575994345428E-05"
        ixy="-5.5656256839282E-07"
        ixz="1.00362368328808E-06"
        iyy="0.000116477053909514"
        iyz="1.07119069997268E-07"
        izz="0.0001129178602649" />
    </inertial>
    <visual>
      <origin
        xyz="0 0 0"
        rpy="0 0 0" />
      <geometry>
        <mesh
          filename="package://flyhopper_rwz/meshes/Link 3.STL" />
      </geometry>
      <material
        name="">
        <color
          rgba="1 1 1 1" />
      </material>
    </visual>
    <collision>
      <origin
        xyz="0 0 0"
        rpy="0 0 0" />
      <geometry>
        <mesh
          filename="package://flyhopper_rwz/meshes/Link 3.STL" />
      </geometry>
    </collision>
  </link>
  <joint
    name="Joint 3"
    type="revolute">
    <origin
      xyz="0.27 0 0"
      rpy="-3.1416 -1.0768 3.1416" />
    <parent
      link="Link 2" />
    <child
      link="Link 3" />
    <axis
      xyz="0 -1 0" />
    <limit
      lower="-1.8295"
      upper="0.7597"
      effort="0"
      velocity="0" />
  </joint>
  <link
    name="rw0">
    <inertial>
      <origin
        xyz="-0.0123550255538276 -6.93889390390723E-17 -4.16333634234434E-17"
        rpy="0 0 0" />
      <mass
        value="0.671107704114979" />
      <inertia
        ixx="0.00298576361315608"
        ixy="6.50521303491303E-19"
        ixz="2.71050543121376E-20"
        iyy="0.00151637106761904"
        iyz="-1.19059222116608E-14"
        izz="0.00151637106761857" />
    </inertial>
    <visual>
      <origin
        xyz="0 0 0"
        rpy="0 0 0" />
      <geometry>
        <mesh
          filename="package://flyhopper_rwz/meshes/rw0.STL" />
      </geometry>
      <material
        name="">
        <color
          rgba="0.647058823529412 0.619607843137255 0.588235294117647 1" />
      </material>
    </visual>
    <collision>
      <origin
        xyz="0 0 0"
        rpy="0 0 0" />
      <geometry>
        <mesh
          filename="package://flyhopper_rwz/meshes/rw0.STL" />
      </geometry>
    </collision>
  </link>
  <joint
    name="joint_rw0"
    type="continuous">
    <origin
      xyz="0.0304055915910213 -0.122329473145273 0.124"
      rpy="2.57078393563195 0 -0.785398163397449" />
    <parent
      link="base_link" />
    <child
      link="rw0" />
    <axis
      xyz="1 0 0" />
  </joint>
  <link
    name="rw1">
    <inertial>
      <origin
        xyz="-0.0123550252793554 3.81639164714898E-17 -2.77555756156289E-17"
        rpy="0 0 0" />
      <mass
        value="0.671107709074598" />
      <inertia
        ixx="0.00298576361560113"
        ixy="3.79470760369927E-19"
        ixz="4.74338450462408E-19"
        iyy="0.00151637106813014"
        iyz="1.18091842728207E-14"
        izz="0.00151637106813061" />
    </inertial>
    <visual>
      <origin
        xyz="0 0 0"
        rpy="0 0 0" />
      <geometry>
        <mesh
          filename="package://flyhopper_rwz/meshes/rw1.STL" />
      </geometry>
      <material
        name="">
        <color
          rgba="0.647058823529412 0.619607843137255 0.588235294117647 1" />
      </material>
    </visual>
    <collision>
      <origin
        xyz="0 0 0"
        rpy="0 0 0" />
      <geometry>
        <mesh
          filename="package://flyhopper_rwz/meshes/rw1.STL" />
      </geometry>
    </collision>
  </link>
  <joint
    name="joint_rw1"
    type="continuous">
    <origin
      xyz="0.0304055915910217 0.122329473145273 0.124"
      rpy="-0.303564166906278 0 0.785398163397446" />
    <parent
      link="base_link" />
    <child
      link="rw1" />
    <axis
      xyz="-1 0 0" />
  </joint>
  <link
    name="rwz">
    <inertial>
      <origin
        xyz="1.89077198692619E-17 -1.366983714898E-17 -0.0137351438260363"
        rpy="0 0 0" />
      <mass
        value="0.528430996906255" />
      <inertia
        ixx="0.000538883816157009"
        ixy="-1.31810864169335E-14"
        ixz="6.35506769697875E-20"
        iyy="0.00053888381615644"
        iyz="-2.51886527013438E-20"
        izz="0.00103704780061135" />
    </inertial>
    <visual>
      <origin
        xyz="0 0 0"
        rpy="0 0 0" />
      <geometry>
        <mesh
          filename="package://flyhopper_rwz/meshes/rwz.STL" />
      </geometry>
      <material
        name="">
        <color
          rgba="0.647058823529412 0.619607843137255 0.588235294117647 1" />
      </material>
    </visual>
    <collision>
      <origin
        xyz="0 0 0"
        rpy="0 0 0" />
      <geometry>
        <mesh
          filename="package://flyhopper_rwz/meshes/rwz.STL" />
      </geometry>
    </collision>
  </link>
  <joint
    name="joint_rwz"
    type="continuous">
    <origin
      xyz="0 0 0.207"
      rpy="0 0 -1.5708" />
    <parent
      link="base_link" />
    <child
      link="rwz" />
    <axis
      xyz="0 0 1" />
  </joint>
</robot>