<?xml version="1.0" encoding="utf-8"?>
<!-- This URDF was automatically created by SolidWorks to URDF Exporter! Originally created by Stephen Brawner (brawner@gmail.com) 
     Commit Version: 1.5.1-0-g916b5db  Build Version: 1.5.7152.31018
     For more information, please see http://wiki.ros.org/sw_urdf_exporter -->
<robot
  name="hopper_rev04">
  <link
    name="base_link">
    <inertial>
      <origin
        xyz="-0.00563798638598889 -0.00067643856951418 0.0752602219607288"
        rpy="0 0 0" />
      <mass
        value="5.53646103481408" />
      <inertia
        ixx="0.00384290238676785"
        ixy="-4.19687319926848E-06"
        ixz="-6.20192772302655E-05"
        iyy="0.00563810128590434"
        iyz="5.31122977745691E-06"
        izz="0.00416003236316103" />
    </inertial>
    <visual>
      <origin
        xyz="0 0 0"
        rpy="0 0 0" />
      <geometry>
        <mesh
          filename="package://hopper_rev04/meshes/base_link.STL" />
      </geometry>
      <material
        name="">
        <color
          rgba="0.898039215686275 0.898039215686275 0.898039215686275 1" />
      </material>
    </visual>
    <collision>
      <origin
        xyz="0 0 0"
        rpy="0 0 0" />
      <geometry>
        <mesh
          filename="package://hopper_rev04/meshes/base_link.STL" />
      </geometry>
    </collision>
  </link>
  <link
    name="Link 0">
    <inertial>
      <origin
        xyz="0.012185125524421 0.0174262909662814 0.00112690524565407"
        rpy="0 0 0" />
      <mass
        value="0.256385541441528" />
      <inertia
        ixx="3.84650063102082E-05"
        ixy="1.53797848955375E-05"
        ixz="-8.48318848133077E-06"
        iyy="0.000172633746370829"
        iyz="1.08260082805317E-06"
        izz="0.00014882244480027" />
    </inertial>
    <visual>
      <origin
        xyz="0 0 0"
        rpy="0 0 0" />
      <geometry>
        <mesh
          filename="package://hopper_rev04/meshes/Link 0.STL" />
      </geometry>
      <material
        name="">
        <color
          rgba="0.898039215686275 0.898039215686275 0.898039215686275 1" />
      </material>
    </visual>
    <collision>
      <origin
        xyz="0 0 0"
        rpy="0 0 0" />
      <geometry>
        <mesh
          filename="package://hopper_rev04/meshes/Link 0.STL" />
      </geometry>
    </collision>
  </link>
  <joint
    name="Joint 0"
    type="revolute">
    <origin
      xyz="0 0 0"
      rpy="0 0.523598775599716 0" />
    <parent
      link="base_link" />
    <child
      link="Link 0" />
    <axis
      xyz="0 -1 0" />
    <limit
      lower="-3.14"
      upper="3.14"
      effort="0"
      velocity="0" />
  </joint>
  <link
    name="Link 1">
    <inertial>
      <origin
        xyz="0.133179166486321 0.00589603896195737 -1.77505057874505E-09"
        rpy="0 0 0" />
      <mass
        value="0.0631106253440014" />
      <inertia
        ixx="2.55536557854724E-06"
        ixy="6.97717913604158E-12"
        ixz="-1.43600164400608E-12"
        iyy="0.000104301672904657"
        iyz="7.22908134333838E-12"
        izz="0.000104300999439092" />
    </inertial>
    <visual>
      <origin
        xyz="0 0 0"
        rpy="0 0 0" />
      <geometry>
        <mesh
          filename="package://hopper_rev04/meshes/Link 1.STL" />
      </geometry>
      <material
        name="">
        <color
          rgba="0.776470588235294 0.756862745098039 0.737254901960784 1" />
      </material>
    </visual>
    <collision>
      <origin
        xyz="0 0 0"
        rpy="0 0 0" />
      <geometry>
        <mesh
          filename="package://hopper_rev04/meshes/Link 1.STL" />
      </geometry>
    </collision>
  </link>
  <joint
    name="Joint 1"
    type="revolute">
    <origin
      xyz="0.1 0 0"
      rpy="3.14159265358979 1.0768315178335 3.14159265358979" />
    <parent
      link="Link 0" />
    <child
      link="Link 1" />
    <axis
      xyz="0 -1 0" />
    <limit
      lower="-0.7597"
      upper="1.8295"
      effort="0"
      velocity="0" />
  </joint>
  <link
    name="Link 2">
    <inertial>
      <origin
        xyz="0.038903229236662 -0.0175829656415458 -0.000627148515337451"
        rpy="0 0 0" />
      <mass
        value="0.288845047026625" />
      <inertia
        ixx="3.46488303945488E-05"
        ixy="-3.25958703038219E-07"
        ixz="5.24928694319893E-06"
        iyy="0.000245584749831182"
        iyz="3.01080240170688E-08"
        izz="0.000226676365115679" />
    </inertial>
    <visual>
      <origin
        xyz="0 0 0"
        rpy="0 0 0" />
      <geometry>
        <mesh
          filename="package://hopper_rev04/meshes/Link 2.STL" />
      </geometry>
      <material
        name="">
        <color
          rgba="0.898039215686275 0.898039215686275 0.898039215686275 1" />
      </material>
    </visual>
    <collision>
      <origin
        xyz="0 0 0"
        rpy="0 0 0" />
      <geometry>
        <mesh
          filename="package://hopper_rev04/meshes/Link 2.STL" />
      </geometry>
    </collision>
  </link>
  <joint
    name="Joint 2"
    type="revolute">
    <origin
      xyz="0 0 0"
      rpy="3.14159265358979 0.553232742317986 3.14159265358979" />
    <parent
      link="base_link" />
    <child
      link="Link 2" />
    <axis
      xyz="0 -1 0" />
    <limit
      lower="-3.14"
      upper="3.14"
      effort="0"
      velocity="0" />
  </joint>
  <link
    name="Link 3">
    <inertial>
      <origin
        xyz="0.101438174462134 -0.00251020587757888 -0.0148532858062159"
        rpy="0 0 0" />
      <mass
        value="0.124857605850282" />
      <inertia
        ixx="1.60742534683083E-05"
        ixy="-5.54606504493174E-07"
        ixz="1.00368288088619E-06"
        iyy="0.000116506435228235"
        iyz="1.07130793494945E-07"
        izz="0.000112946754257471" />
    </inertial>
    <visual>
      <origin
        xyz="0 0 0"
        rpy="0 0 0" />
      <geometry>
        <mesh
          filename="package://hopper_rev04/meshes/Link 3.STL" />
      </geometry>
      <material
        name="">
        <color
          rgba="1 1 1 1" />
      </material>
    </visual>
    <collision>
      <origin
        xyz="0 0 0"
        rpy="0 0 0" />
      <geometry>
        <mesh
          filename="package://hopper_rev04/meshes/Link 3.STL" />
      </geometry>
    </collision>
  </link>
  <joint
    name="Joint 3"
    type="revolute">
    <origin
      xyz="0.270000000042219 0 0"
      rpy="-3.14159265358979 -1.07683151743819 3.14159265358979" />
    <parent
      link="Link 2" />
    <child
      link="Link 3" />
    <axis
      xyz="0 -1 0" />
    <limit
      lower="-1.8295"
      upper="0.7597"
      effort="0"
      velocity="0" />
  </joint>
  <link
    name="rw0">
    <inertial>
      <origin
        xyz="-0.0106867499463367 -7.59786659976225E-09 2.70428182624904E-09"
        rpy="0 0 0" />
      <mass
        value="0.715641175075331" />
      <inertia
        ixx="0.00312227321188979"
        ixy="-1.82809740652615E-12"
        ixz="1.21129033520584E-11"
        iyy="0.0015857069659752"
        iyz="7.43838571073003E-09"
        izz="0.00158570710797415" />
    </inertial>
    <visual>
      <origin
        xyz="0 0 0"
        rpy="0 0 0" />
      <geometry>
        <mesh
          filename="package://hopper_rev04/meshes/rw0.STL" />
      </geometry>
      <material
        name="">
        <color
          rgba="0.647058823529412 0.619607843137255 0.588235294117647 1" />
      </material>
    </visual>
    <collision>
      <origin
        xyz="0 0 0"
        rpy="0 0 0" />
      <geometry>
        <mesh
          filename="package://hopper_rev04/meshes/rw0.STL" />
      </geometry>
    </collision>
  </link>
  <joint
    name="joint_rw0"
    type="continuous">
    <origin
      xyz="0.0539522474045338 -0.0798869360369105 0.116"
      rpy="3.03065856040946 0 -0.785398163397448" />
    <parent
      link="base_link" />
    <child
      link="rw0" />
    <axis
      xyz="1 0 0" />
  </joint>
  <link
    name="rw1">
    <inertial>
      <origin
        xyz="-0.0106867499463733 7.59763008062464E-09 -2.70429836857211E-09"
        rpy="0 0 0" />
      <mass
        value="0.715641175076258" />
      <inertia
        ixx="0.00312227321188979"
        ixy="1.82797369905827E-12"
        ixz="-1.21129122035527E-11"
        iyy="0.00158570696597532"
        iyz="7.43838570552755E-09"
        izz="0.00158570710797428" />
    </inertial>
    <visual>
      <origin
        xyz="0 0 0"
        rpy="0 0 0" />
      <geometry>
        <mesh
          filename="package://hopper_rev04/meshes/rw1.STL" />
      </geometry>
      <material
        name="">
        <color
          rgba="0.647058823529412 0.619607843137255 0.588235294117647 1" />
      </material>
    </visual>
    <collision>
      <origin
        xyz="0 0 0"
        rpy="0 0 0" />
      <geometry>
        <mesh
          filename="package://hopper_rev04/meshes/rw1.STL" />
      </geometry>
    </collision>
  </link>
  <joint
    name="joint_rw1"
    type="continuous">
    <origin
      xyz="0.0539522474045338 0.0785617146494409 0.116"
      rpy="-0.0304329711040622 0 0.785398163397448" />
    <parent
      link="base_link" />
    <child
      link="rw1" />
    <axis
      xyz="-1 0 0" />
  </joint>
  <link
    name="rwz">
    <inertial>
      <origin
        xyz="-2.31585584042904E-16 -6.82787160144471E-15 -0.0143212590966127"
        rpy="0 0 0" />
      <mass
        value="0.480621066769277" />
      <inertia
        ixx="0.00034873599560601"
        ixy="-1.31810819317055E-14"
        ixz="-2.56270728099723E-20"
        iyy="0.000348735995605441"
        iyz="-1.07540225610664E-16"
        izz="0.000659111377573692" />
    </inertial>
    <visual>
      <origin
        xyz="0 0 0"
        rpy="0 0 0" />
      <geometry>
        <mesh
          filename="package://hopper_rev04/meshes/rwz.STL" />
      </geometry>
      <material
        name="">
        <color
          rgba="0.647058823529412 0.619607843137255 0.588235294117647 1" />
      </material>
    </visual>
    <collision>
      <origin
        xyz="0 0 0"
        rpy="0 0 0" />
      <geometry>
        <mesh
          filename="package://hopper_rev04/meshes/rwz.STL" />
      </geometry>
    </collision>
  </link>
  <joint
    name="joint_rwz"
    type="continuous">
    <origin
      xyz="-0.0666999999998561 -0.000662610693735013 0.101500000000095"
      rpy="0 0 -1.57079632679463" />
    <parent
      link="base_link" />
    <child
      link="rwz" />
    <axis
      xyz="0 0 1" />
  </joint>
</robot>